Workbook

Sheet Hoja1
A2: Fecha de Inicio | B2: (Todas)
A3: AREACH | B3: (Todas)
A5: Etiquetas de fila | B5: Cuenta de IDSDNCA | C5: Suma de Asistentes Totales
A6: Subdirección de Administración de Servicios para Exploración y Producción | B6: 65 | C6: 601
A7: Subdirección de Coordinación Operativa y Comercial | B7: 173 | C7: 776
A8: Subdirección de Exploración | B8: 30 | C8: 180
A9: Subdirección de Exploración y Producción por Contratos y Asociaciones | B9: 2 | C9: 2
A10: Subdirección de Producción Región Marina Suroeste | B10: 17 | C10: 198
A11: Subdirección de Producción Región Sur | B11: 230 | C11: 2814
A12: Subdirección de Seguridad, Salud en el Trabajo y Protección Ambiental | B12: 122 | C12: 976
A13: Subdirección de Producción Región Marina Noreste | B13: 65 | C13: 1046
A14: Subdirección de Perforación y Mantenimiento de Pozos | B14: 138 | C14: 1147
A15: Subdirección de Producción Región Norte | B15: 104 | C15: 956
A16: Total general | B16: 946 | C16: 8696
A20: Mes | B20: (Varios elementos)
A21: AREACH | B21: (Todas)
A22: Fecha de Termino | B22: (Todas)
A24: Etiquetas de fila | B24: Cuenta de IDSDNCA | C24: Suma de Asistentes Totales
A25: Subdirección de Administración de Servicios para Exploración y Producción | B25: 25 | C25: 264
A26: Subdirección de Exploración | B26: 12 | C26: 80
A27: Subdirección de Producción Región Marina Suroeste | B27: 3 | C27: 31
A28: Subdirección de Producción Región Sur | B28: 38 | C28: 415
A29: Subdirección de Seguridad, Salud en el Trabajo y Protección Ambiental | B29: 25 | C29: 230
A30: Subdirección de Perforación y Mantenimiento de Pozos | B30: 2 | C30: 18
A31: Subdirección de Producción Región Norte | B31: 33 | C31: 300
A32: Total general | B32: 138 | C32: 1338

Sheet PICADE
A6: Cons | B6: ID_SAP | C6: AREACH | D6: IDSDNCA | E6: Subdirección | F6: Gerencia/Activo | G6: Curso | H6: Tipo de Impartición | I6: Ficha | J6: Instructor | K6: Duración (Horas) | L6: Días | M6: Asistentes Totales | N6: Fecha de Inicio | O6: Fecha de Termino | P6: Mes
A7: 1 | C7: Ciudad del Carmen | D7: 23298 | E7: Subdirección de Administración de Servicios para Exploración y Producción | F7: Coordinación de Servicios Marinos y de Mantenimiento, Confiabilidad y Construcción de Infraestructura | G7: REACREDITACION DE SIGNATARIOS DEL SPPTR (RSPTR) | H7: PRESENCIAL | I7: 350060 | J7: Hernan Zurita Dominguez | K7: 8 | L7: 1 | M7: 13 | N7: 05/02/2021 | O7: 44232 | P7: Febrero
A8: 2 | C8: CIUDAD DEL CARMEN, CAMPECHE | D8: 23281 | E8: Subdirección de Administración de Servicios para Exploración y Producción | F8: Coordinación de Servicios Marinos y de Mantenimiento, Confiabilidad y Construcción de Infraestructura | G8: SISTEMA DE PERMISOS PARA TRABAJOS CON RIESGO (SPTR) | H8: PRESENCIAL | I8: 374253 | J8: Eduardo Gonzalez Rodriguez | K8: 24 | L8: 3 | M8: 8 | N8: 15/02/2021 | O8: 44244 | P8: Febrero
A9: 3 | C9: CIUDAD DEL CARMEN, CAMPECHE | D9: 23297 | E9: Subdirección de Administración de Servicios para Exploración y Producción | F9: Coordinación de Servicios Marinos y de Mantenimiento, Confiabilidad y Construcción de Infraestructura | G9: REACREDITACION DE SIGNATARIOS DEL SPPTR (RSPTR) | H9: PRESENCIAL | I9: 436665 | J9: Francisco Antonio Castro Reyes | K9: 8 | L9: 1 | M9: 11 | N9: 17/02/2021 | O9: 44244 | P9: Febrero
A10: 4 | C10: CIUDAD DEL CARMEN, CAMPECHE | D10: 23300 | E10: Subdirección de Administración de Servicios para Exploración y Producción | F10: Coordinación de Servicios Marinos y de Mantenimiento, Confiabilidad y Construcción de Infraestructura | G10: REACREDITACION DE SIGNATARIOS DEL SPPTR (RSPTR) | H10: PRESENCIAL | I10: 436665 | J10: Francisco Antonio Castro Reyes | K10: 8 | L10: 1 | M10: 10 | N10: 18/02/2021 | O10: 44245 | P10: Febrero
A11: 5 | C11: CIUDAD DEL CARMEN, CAMPECHE | D11: 23301 | E11: Subdirección de Administración de Servicios para Exploración y Producción | F11: Coordinación de Servicios Marinos y de Mantenimiento, Confiabilidad y Construcción de Infraestructura | G11: REACREDITACION DE SIGNATARIOS DEL SPPTR (RSPTR) | H11: PRESENCIAL | I11: 436665 | J11: Francisco Antonio Castro Reyes | K11: 8 | L11: 1 | M11: 6 | N11: 19/02/2021 | O11: 44246 | P11: Febrero
A12: 6 | C12: CIUDAD DEL CARMEN, CAMPECHE | D12: 23299 | E12: Subdirección de Administración de Servicios para Exploración y Producción | F12: Coordinación de Servicios Marinos y de Mantenimiento, Confiabilidad y Construcción de Infraestructura | G12: REACREDITACION DE SIGNATARIOS DEL SPPTR (RSPTR) | H12: PRESENCIAL | I12: 436665 | J12: Francisco Antonio Castro Reyes | K12: 8 | L12: 1 | M12: 11 | N12: 22/02/2021 | O12: 44249 | P12: Febrero
A13: 7 | C13: CIUDAD DEL CARMEN, CAMPECHE | D13: 23302 | E13: Subdirección de Administración de Servicios para Exploración y Producción | F13: Coordinación de Servicios Marinos y de Mantenimiento, Confiabilidad y Construcción de Infraestructura | G13: REACREDITACION DE SIGNATARIOS DEL SPPTR (RSPTR) | H13: PRESENCIAL | I13: 436665 | J13: Francisco Antonio Castro Reyes | K13: 8 | L13: 1 | M13: 14 | N13: 23/02/2021 | O13: 44250 | P13: Febrero
A14: 8 | C14: CIUDAD DEL CARMEN, CAMPECHE | D14: 23282 | E14: Subdirección de Administración de Servicios para Exploración y Producción | F14: Coordinación de Servicios Marinos y de Mantenimiento, Confiabilidad y Construcción de Infraestructura | G14: SISTEMA DE PERMISOS PARA TRABAJOS CON RIESGO (SPTR) | H14: PRESENCIAL | I14: 374253 | J14: Eduardo Gonzalez Rodriguez | K14: 24 | L14: 3 | M14: 10 | N14: 01/03/2021 | O14: 44258 | P14: Marzo
A15: 9 | C15: CIUDAD DEL CARMEN, CAMPECHE | D15: 23304 | E15: Subdirección de Administración de Servicios para Exploración y Producción | F15: Coordinación de Servicios Marinos y de Mantenimiento, Confiabilidad y Construcción de Infraestructura | G15: REACREDITACION DE SIGNATARIOS DEL SPPTR (RSPTR) | H15: PRESENCIAL | I15: 350060 | J15: Hernan Zurita Dominguez | K15: 8 | L15: 1 | M15: 10 | N15: 04/03/2021 | O15: 44259 | P15: Marzo
A16: 10 | C16: CIUDAD DEL CARMEN, CAMPECHE | D16: 23305 | E16: Subdirección de Administración de Servicios para Exploración y Producción | F16: Coordinación de Servicios Marinos y de Mantenimiento, Confiabilidad y Construcción de Infraestructura | G16: REACREDITACION DE SIGNATARIOS DEL SPPTR (RSPTR) | H16: PRESENCIAL | I16: 350060 | J16: Hernan Zurita Dominguez | K16: 8 | L16: 1 | M16: 12 | N16: 05/03/2021 | O16: 44260 | P16: Marzo
A17: 11 | C17: CIUDAD DEL CARMEN, CAMPECHE | D17: 23303 | E17: Subdirección de Administración de Servicios para Exploración y Producción | F17: Coordinación de Servicios Marinos y de Mantenimiento, Confiabilidad y Construcción de Infraestructura | G17: REACREDITACION DE SIGNATARIOS DEL SPPTR (RSPTR) | H17: PRESENCIAL | I17: 436665 | J17: Francisco Antonio Castro Reyes | K17: 8 | L17: 1 | M17: 11 | N17: 16/03/2021 | O17: 44271 | P17: Marzo
A18: 12 | C18: CIUDAD DEL CARMEN, CAMPECHE | D18: 23307 | E18: Subdirección de Administración de Servicios para Exploración y Producción | F18: Coordinación de Servicios Marinos y de Mantenimiento, Confiabilidad y Construcción de Infraestructura | G18: REACREDITACION DE SIGNATARIOS DEL SPPTR (RSPTR) | H18: PRESENCIAL | I18: 436665 | J18: Francisco Antonio Castro Reyes | K18: 8 | L18: 1 | M18: 11 | N18: 17/03/2021 | O18: 44272 | P18: Marzo
... A31: 25 | C31: CIUDAD DEL CARMEN, CAMPECHE | D31: 24913 | E31: Subdirección de Coordinación Operativa y Comercial | F31: Gerencia de Coordinación de Operaciones | G31: REVALIDACION DE SEGURIDAD Y SOBREVIVENCIA COSTA AFUERA (RSSCA) | H31: PRESENCIAL | I31: 354951 | J31: Raul Armando Garza Torre | K31: 16 | L31: 2 | M31: 1 | N31: 11/05/2021 | O31: 44328 | P31: Mayo
A32: 26 | C32: CIUDAD DEL CARMEN, CAMPECHE | D32: 26163 | E32: Subdirección de Perforación y Mantenimiento de Pozos | F32: Gerencia de Perforación y Reparación de Pozos Marina | G32: SEGURIDAD Y SOBREVIVENCIA COSTA AFUERA (SSCA) | H32: PRESENCIAL | I32: 350060 | J32: Hernan Zurita Dominguez | K32: 24 | L32: 3 | M32: 12 | N32: 44329 | O32: 44331 | P32: Mayo
A33: 27 | C33: CIUDAD DEL CARMEN, CAMPECHE | D33: 27340 | E33: Subdirección de Perforación y Mantenimiento de Pozos | F33: Gerencia de Perforación y Reparación de Pozos Marina | G33: SISTEMA DE PERMISOS PARA TRABAJOS CON RIESGO (SPTR) | H33: PRESENCIAL | I33: 419491 | J33: Julio Andres Barrios Almazan | K33: 24 | L33: 3 | M33: 12 | N33: 13/05/2021 | O33: 44331 | P33: Mayo
A34: 28 | C34: CIUDAD DEL CARMEN, CAMPECHE | D34: 29663 | E34: Subdirección de Seguridad, Salud en el Trabajo y Protección Ambiental | F34: Gerencia de Seguridad, Salud en el Trabajo y Protección Ambiental Región Marina | G34: PREVENCION DE RIESGOS LABORALES | H34: A DISTANCIA | I34: 206830 | J34: José Trinidad Osorno Requena | K34: 16 | L34: 2 | M34: 8 | N34: 13/05/2021 | O34: 44334 | P34: Mayo
A35: 29 | C35: CIUDAD DEL CARMEN, CAMPECHE | D35: 24914 | E35: Subdirección de Coordinación Operativa y Comercial | F35: Gerencia de Coordinación de Operaciones | G35: REVALIDACION DE SEGURIDAD Y SOBREVIVENCIA COSTA AFUERA (RSSCA) | H35: PRESENCIAL | I35: 354951 | J35: Raul Armando Garza Torre | K35: 16 | L35: 2 | M35: 1 | N35: 18/05/2021 | O35: 44335 | P35: Mayo
A36: 30 | C36: CIUDAD DEL CARMEN, CAMPECHE | D36: 27334 | E36: Subdirección de Perforación y Mantenimiento de Pozos | F36: Gerencia de Perforación y Reparación de Pozos Marina | G36: SISTEMA DE PERMISOS PARA TRABAJOS CON RIESGO (SPTR) | H36: PRESENCIAL | I36: 419491 | J36: Julio Andres Barrios Almazan | K36: 24 | L36: 3 | M36: 10 | N36: 19/05/2021 | O36: 44337 | P36: Mayo
A37: 31 | C37: CIUDAD DEL CARMEN, CAMPECHE | D37: 27826 | E37: Subdirección de Perforación y Mantenimiento de Pozos | F37: Gerencia de Servicios a Pozos | G37: BASICO DE SEGURIDAD (BS) | H37: PRESENCIAL | I37: 350060 | J37: Hernan Zurita Dominguez | K37: 16 | L37: 2 | M37: 13 | N37: 21/05/2021 | O37: 44338 | P37: Mayo
A38: 32 | C38: CIUDAD DEL CARMEN, CAMPECHE | D38: 21481 | E38: Subdirección de Producción Región Marina Noreste | F38: Gerencia de Mantenimiento, Confiabilidad y Construcción | G38: REACREDITACION DE SIGNATARIOS DEL SPPTR (RSPTR) | H38: A DISTANCIA | I38: 458886 | J38: Edgar Mendoza Rodriguez | K38: 8 | L38: 1 | M38: 11 | N38: 24/05/2021 | O38: 44340 | P38: Mayo
A39: 33 | C39: CIUDAD DEL CARMEN, CAMPECHE | D39: 27335 | E39: Subdirección de Perforación y Mantenimiento de Pozos | F39: Gerencia de Perforación y Reparación de Pozos Marina | G39: SISTEMA DE PERMISOS PARA TRABAJOS CON RIESGO (SPTR) | H39: PRESENCIAL | I39: 419491 | J39: Julio Andres Barrios Almazan | K39: 24 | L39: 3 | M39: 10 | N39: 22/05/2021 | O39: 44340 | P39: Mayo
A40: 34 | C40: CIUDAD DEL CARMEN, CAMPECHE | D40: 24750 | E40: Subdirección de Coordinación Operativa y Comercial | F40: Gerencia de Coordinación de Operaciones | G40: SISTEMA DE PERMISOS PARA TRABAJOS CON RIESGO (SPTR) | H40: PRESENCIAL | I40: 354951 | J40: Raul Armando Garza Torre | K40: 24 | L40: 3 | M40: 5 | N40: 26/05/2021 | O40: 44344 | P40: Mayo
A41: 35 | C41: CIUDAD DEL CARMEN, CAMPECHE | D41: 28027 | E41: Subdirección de Perforación y Mantenimiento de Pozos | F41: Gerencia de Servicios a Pozos | G41: SOBREVIVENCIA EN EL MAR (SM) | H41: PRESENCIAL | I41: CASES | J41: INSTRUCTOR CASES . | K41: 16 | L41: 2 | M41: 8 | N41: 27/05/2021 | O41: 44344 | P41: Mayo
A42: 36 | C42: CIUDAD DEL CARMEN, CAMPECHE | D42: 27352 | E42: Subdirección de Perforación y Mantenimiento de Pozos | F42: Gerencia de Perforación y Reparación de Pozos Marina | G42: SISTEMA DE PERMISOS PARA TRABAJOS CON RIESGO (SPTR) | H42: PRESENCIAL | I42: 489671 | J42: Pedro Zacarias Alcocer | K42: 24 | L42: 3 | M42: 12 | N42: 27/05/2021 | O42: 44345 | P42: Mayo
A43: 37 | C43: CIUDAD DEL CARMEN, CAMPECHE | D43: 21482 | E43: Subdirección de Producción Región Marina Noreste | F43: Gerencia de Mantenimiento, Confiabilidad y Construcción | G43: REACREDITACION DE SIGNATARIOS DEL SPPTR (RSPTR) | H43: A DISTANCIA | I43: 458886 | J43: Edgar Mendoza Rodriguez | K43: 8 | L43: 1 | M43: 20 | N43: 01/06/2021 | O43: 44348 | P43: Junio
A44: 38 | C44: CIUDAD DEL CARMEN, CAMPECHE | D44: 21446 | E44: Subdirección de Producción Región Marina Noreste | F44: Gerencia de Mantenimiento, Confiabilidad y Construcción | G44: BASICO DE SEGURIDAD (BS) | H44: PRESENCIAL | I44: 354951 | J44: Raul Armando Garza Torre | K44: 16 | L44: 2 | M44: 10 | N44: 02/06/2021 | O44: 44350 | P44: Junio
A45: 39 | C45: CIUDAD DEL CARMEN, CAMPECHE | D45: 21447 | E45: Subdirección de Producción Región Marina Noreste | F45: Gerencia de Mantenimiento, Confiabilidad y Construcción | G45: BASICO DE SEGURIDAD (BS) | H45: A DISTANCIA | I45: 354951 | J45: Raul Armando Garza Torre | K45: 16 | L45: 2 | M45: 22 | N45: 08/06/2021 | O45: 44356 | P45: Junio
A46: 40 | C46: CIUDAD DEL CARMEN, CAMPECHE | D46: 28026 | E46: Subdirección de Perforación y Mantenimiento de Pozos | F46: Gerencia de Servicios a Pozos | G46: SOBREVIVENCIA EN EL MAR (SM) | H46: PRESENCIAL | I46: CASES | J46: INSTRUCTOR CASES . | K46: 16 | L46: 2 | M46: 7 | N46: 08/06/2021 | O46: 44356 | P46: Junio
A47: 41 | C47: CIUDAD DEL CARMEN, CAMPECHE | D47: 22169 | E47: Subdirección de Seguridad, Salud en el Trabajo y Protección Ambiental | F47: Gerencia de Seguridad, Salud en el Trabajo y Protección Ambiental Región Marina | G47: BRIGADAS DE BUSQUEDA Y RESCATE (BBR) | H47: PRESENCIAL | I47: 389970 | J47: Azariel Lopez Lara | K47: 24 | L47: 3 | M47: 12 | N47: 09/06/2021 | O47: 44358 | P47: Junio
A48: 42 | C48: CIUDAD DEL CARMEN, CAMPECHE | D48: 24591 | E48: Subdirección de Seguridad, Salud en el Trabajo y Protección Ambiental | F48: Gerencia de Seguridad, Salud en el Trabajo y Protección Ambiental Región Marina | G48: SEGURIDAD Y SOBREVIVENCIA COSTA AFUERA (SSCA) | H48: PRESENCIAL | I48: 354951 | J48: Raul Armando Garza Torre | K48: 24 | L48: 3 | M48: 12 | N48: 10/06/2021 | O48: 44359 | P48: Junio
A49: 43 | C49: CIUDAD DEL CARMEN, CAMPECHE | D49: 29681 | E49: Subdirección de Seguridad, Salud en el Trabajo y Protección Ambiental | F49: Gerencia de Seguridad, Salud en el Trabajo y Protección Ambiental Región Marina | G49: DISCIPLINA OPERATIVA | H49: A DISTANCIA | I49: 350060 | J49: Hernan Zurita Dominguez | K49: 16 | L49: 2 | M49: 14 | N49: 10/06/2021 | O49: 44363 | P49: Junio
A50: 44 | C50: CIUDAD DEL CARMEN, CAMPECHE | D50: 24916 | E50: Subdirección de Coordinación Operativa y Comercial | F50: Gerencia de Coordinación de Operaciones | G50: REVALIDACION DE SEGURIDAD Y SOBREVIVENCIA COSTA AFUERA (RSSCA) | H50: PRESENCIAL | I50: 354951 | J50: Raul Armando Garza Torre | K50: 16 | L50: 2 | M50: 7 | N50: 17/06/2021 | O50: 44365 | P50: Junio
A51: 45 | C51: CIUDAD DEL CARMEN, CAMPECHE | D51: 27336 | E51: Subdirección de Perforación y Mantenimiento de Pozos | F51: Gerencia de Perforación y Reparación de Pozos Marina | G51: SISTEMA DE PERMISOS PARA TRABAJOS CON RIESGO (SPTR) | H51: PRESENCIAL | I51: 419491 | J51: Julio Andres Barrios Almazan | K51: 24 | L51: 3 | M51: 7 | N51: 16/06/2021 | O51: 44365 | P51: Junio
A52: 46 | C52: CIUDAD DEL CARMEN, CAMPECHE | D52: 21483 | E52: Subdirección de Producción Región Marina Noreste | F52: Gerencia de Mantenimiento, Confiabilidad y Construcción | G52: REACREDITACION DE SIGNATARIOS DEL SPPTR (RSPTR) | H52: A DISTANCIA | I52: 458886 | J52: Edgar Mendoza Rodriguez | K52: 8 | L52: 1 | M52: 13 | N52: 21/06/2021 | O52: 44368 | P52: Junio
A53: 47 | C53: CIUDAD DEL CARMEN, CAMPECHE | D53: 27337 | E53: Subdirección de Perforación y Mantenimiento de Pozos | F53: Gerencia de Perforación y Reparación de Pozos Marina | G53: SISTEMA DE PERMISOS PARA TRABAJOS CON RIESGO (SPTR) | H53: PRESENCIAL | I53: 419491 | J53: Julio Andres Barrios Almazan | K53: 24 | L53: 3 | M53: 7 | N53: 19/06/2021 | O53: 21/06/2021 | P53: Junio
A54: 48 | C54: CIUDAD DEL CARMEN, CAMPECHE | D54: 24592 | E54: Subdirección de Seguridad, Salud en el Trabajo y Protección Ambiental | F54: Gerencia de Seguridad, Salud en el Trabajo y Protección Ambiental Región Marina | G54: SEGURIDAD Y SOBREVIVENCIA COSTA AFUERA (SSCA) | H54: PRESENCIAL | I54: 354951 | J54: Raul Armando Garza Torre | K54: 24 | L54: 3 | M54: 12 | N54: 24/06/2021 | O54: 26/06/2021 | P54: Junio
A55: 49 | C55: CIUDAD DEL CARMEN, CAMPECHE | D55: 25933 | E55: Subdirección de Perforación y Mantenimiento de Pozos | F55: Gerencia de Perforación y Reparación de Pozos Marina | G55: BRIGADAS CONTRAINCENDIOS (BCII) | H55: PRESENCIAL | I55: 489671 | J55: Pedro Zacarias Alcocer | K55: 24 | L55: 3 | M55: 5 | N55: 24/06/2021 | O55: 26/06/2021 | P55: Junio
A56: 50 | C56: CIUDAD DEL CARMEN, CAMPECHE | D56: 26157 | E56: Subdirección de Perforación y Mantenimiento de Pozos | F56: Gerencia de Perforación y Reparación de Pozos Marina | G56: SEGURIDAD Y SOBREVIVENCIA COSTA AFUERA (SSCA) | H56: PRESENCIAL | I56: 411339 | J56: Carlos Alfredo Ramirez Barrenechea | K56: 24 | L56: 3 | M56: 12 | N56: 25/06/2021 | O56: 27/06/2021 | P56: Junio
A57: 51 | C57: CIUDAD DEL CARMEN, CAMPECHE | D57: 21432 | E57: Subdirección de Producción Región Marina Noreste | F57: Gerencia de Mantenimiento, Confiabilidad y Construcción | G57: REVALIDACION DE SEGURIDAD Y SOBREVIVENCIA COSTA AFUERA (RSSCA) | H57: PRESENCIAL | I57: 389970 | J57: Azariel Lopez Lara | K57: 16 | L57: 2 | M57: 19 | N57: 29/06/2021 | O57: 30/06/2021 | P57: Junio
...

Sheet Seguimiento
T2: Fecha de corte
T3: 44561
I5: Periodo
C6: PICADE Autorizado | E6: Vencidos antes de PICADE | G6: PICADE Ajustado con LN | I6: 01 de ene al | L6: =CONCATENATE(TEXT(T3, "dd"), " de ", TEXT(T3, "mmmm")," de ",TEXT(T3,"aaaa")) -> 31 de diciembre de 2021
B7: Zona | C7: Cursos | D7: Capacitandos | E7: Cursos | F7: Capacitandos | G7: Cursos | H7: Capacitandos | I7: Programados | J7: Capacitandos | K7: Realizados en prog. | L7: Adicionales | M7: Total Realizados | N7: Capacitandos | O7: Capacitandos Adicionales | P7: Cancelados | Q7: Cumplimiento en el periodo (%) | R7: Avance del PICADE ajustado (%)
B8: Norte | C8: =C26 -> 229 | D8: =D26 -> 1879 | E8: =E26 -> 31 | F8: =F26 -> 248 | G8: =G26 -> 198 | H8: =H26 -> 1631 | I8: =I26 -> 198 | J8: =J26 -> 1631 | ... L8: =L26 -> 5 | M8: =K8+L8 -> 172 | N8: =N26 -> 1135 | O8: =Adicionales!G5 -> 42 | P8: =P26 -> 31 | Q8: =IFERROR(M8/(I8+L8), "-") -> 0.84729064 | R8: =IFERROR(M8/(G8+L8), "-") -> 0.84729064 | S8: =+K8/I8 -> 0.84343434
B9: Sur | C9: =C37 -> 257 | D9: =D37 -> 3015 | E9: =E37 -> 27 | F9: =F37 -> 265 | G9: =G37 -> 139 | H9: =H37 -> 1801 | I9: =I37 -> 139 | J9: =J37 -> 1801 | K9: =K37 -> 69 | L9: =Adicionales!F4 -> 34 | M9: =K9+L9 -> 103 | N9: =N37 -> 585 | O9: =Adicionales!G4 -> 310 | P9: =P37 -> 120 | Q9: =IFERROR(M9/(I9+L9), "-") -> 0.59537572 | R9: =IFERROR(M9/(G9+L9), "-") -> 0.59537572 | S9: =+K9/I9 -> 0.49640288
B10: Cd. Carmen | C10: ='Cd. Carmen'!F2 -> 183 | D10: ='Cd. Carmen'!F3 -> 2126 | E10: ='Cd. Carmen'!H1 -> 19 | F10: ='Cd. Carmen'!H2 -> 208 | G10: ='Cd. Carmen'!L4 -> 164 | H10: ='Cd. Carmen'!L3 -> 1918 | I10: ='Cd. Carmen'!F4 -> 164 | J10: ='Cd. Carmen'!F5 -> 1918 | K10: ='Cd. Carmen'!H3 -> 95 | L10: =Adicionales!F3 -> 38 | M10: =K10+L10 -> 133 | N10: ='Cd. Carmen'!H4 -> 843 | O10: =+Adicionales!G3 -> 398 | P10: ='Cd. Carmen'!H5 -> 71 | Q10: =IFERROR(M10/(I10+L10), "-") -> 0.65841584 | R10: =IFERROR(M10/(G10+L10), "-") -> 0.65841584 | S10: =+K10/I10 -> 0.57926829
B11: Dos Bocas | C11: ='Dos Bocas'!G2 -> 188 | D11: ='Dos Bocas'!G3 -> 1068 | E11: ='Dos Bocas'!I1 -> 3 | F11: ='Dos Bocas'!I2 -> 28 | G11: ='Dos Bocas'!M4 -> 88 | H11: ='Dos Bocas'!M3 -> 928 | I11: ='Dos Bocas'!G4 -> 88 | J11: ='Dos Bocas'!G5 -> 928 | K11: ='Dos Bocas'!I3 -> 83 | L11: =Adicionales!F2 -> 23 | M11: =K11+L11 -> 106 | N11: ='Dos Bocas'!I4 -> 723 | O11: =+Adicionales!G2 -> 284 | P11: ='Dos Bocas'!I5 -> 6 | Q11: =IFERROR(M11/(I11+L11), "-") -> 0.95495495 | R11: =IFERROR(M11/(G11+L11), "-") -> 0.95495495 | S11: =+K11/I11 -> 0.94318182
B12: Perforación | C12: =Perforación!F2 -> 81 | D12: =Perforación!F3 -> 579 | E12: =Perforación!H1 -> 1 | F12: =Perforación!H2 -> 10 | G12: =C12-E12 -> 80 | H12: =D12-F12 -> 569 | I12: =Perforación!F4 -> 80 | J12: =Perforación!F5 -> 569 | K12: =Perforación!H3 -> 32 | L12: =Adicionales!F6 -> 1 | M12: =K12+L12 -> 33 | N12: =Perforación!H4 -> 210 | O12: =Adicionales!G6 -> 5 | P12: =Perforación!H5 -> 48 | Q12: =IFERROR(M12/(I12+L12), "-") -> 0.40740741 | R12: =IFERROR(M12/(G12+L12), "-") -> 0.40740741 | S12: =+K12/I12 -> 0.4
B13: Cd. Méx. | C13: ='Cd. Méx'!F2 -> 4 | D13: ='Cd. Méx'!F3 -> 8 | E13: ='Cd. Méx'!H1 -> 0 | F13: ='Cd. Méx'!H2 -> 0 | G13: ='Cd. Méx'!L4 -> 0 | H13: ='Cd. Méx'!L3 -> 0 | I13: 0 | J13: 0 | K13: ='Cd. Méx'!H3 -> 0 | M13: =K13+L13 -> 0 | N13: ='Cd. Méx'!H4 -> 0 | P13: ='Cd. Méx'!H5 -> 2 | Q13: =IFERROR(M13/(I13+L13), "-") -> - | R13: =IFERROR(M13/(G13+L13), "-") -> - | S13: =+K13/I13 -> #DIV/0!
B14: Sede | C14: =Sede!F2 -> 4 | D14: =Sede!F3 -> 21 | E14: =Sede!H1 -> 0 | F14: =Sede!H2 -> 0 | G14: =Sede!L4 -> 3 | H14: =Sede!L3 -> 17 | I14: 3 | J14: 17 | K14: =Sede!H3 -> 0 | M14: =K14+L14 -> 0 | N14: =Sede!H4 -> 0 | P14: =Sede!H5 -> 4 | Q14: =IFERROR(M14/(I14+L14), "-") -> 0 | R14: =IFERROR(M14/(G14+L14), "-") -> 0 | S14: =+K14/I14 -> 0
B15: Total PEP | C15: =SUM(C8:C14) -> 946 | D15: =SUM(D8:D14) -> 8696 | E15: =SUM(E8:E14) -> 81 | F15: =SUM(F8:F14) -> 759 | G15: =SUM(G8:G14) -> 672 | H15: =SUM(H8:H14) -> 6864 | I15: =SUM(I8:I14) -> 672 | J15: =SUM(J8:J14) -> 6864 | ... L15: =SUM(L8:L14) -> 101 | M15: 547 | N15: =SUM(N8:N14) -> 3496 | O15: =SUM(O8:O14) -> 1039 | P15: =SUM(P8:P14) -> 282 | Q15: =IFERROR(M15/(I15+L15), "-") -> 0.7076326 | R15: =IFERROR(M15/(G15+L15), "-") -> 0.7076326 | S15: =+K15/I15 -> 0.66369048
C17: =+E15+G15+G17 -> 753
I18: Periodo
C19: PICADE Autorizado | E19: Vencidos antes de PICADE | G19: PICADE Ajustado con LN | I19: 19 de abril al | L19: =CONCATENATE(TEXT(T3, "dd"), " de ", TEXT(T3, "mmmm")," de ",TEXT(T3,"aaaa")) -> 31 de diciembre de 2021
B20: Región Norte | C20: Cursos | D20: Capacitandos | E20: Cursos | F20: Capacitandos | G20: Cursos | H20: Capacitandos | I20: Programados | J20: Capacitandos | K20: Realizados en prog. | L20: Adicionales | M20: Realizados | N20: Capacitandos | O20: Capacitandos Adicionales | P20: Cancelados | Q20: Cumplimiento en el periodo (%) | R20: Avance del PICADE ajustado (%)
B21: Reynosa | C21: =Reynosa!F2 -> 56 | D21: =Reynosa!F3 -> 586 | E21: =Reynosa!H1 -> 0 | F21: =Reynosa!H2 -> 0 | G21: =Reynosa!F2 -> 56 | H21: =D21 -> 586 | I21: =Reynosa!F4 -> 56 | J21: =Reynosa!F5 -> 586 | K21: =Reynosa!H3 -> 54 | L21: 5 | M21: =K21+L21 -> 59 | N21: =Reynosa!H4 -> 497 | O21: 42 | P21: =Reynosa!H5 -> 2 | Q21: =IFERROR(M21/(I21+L21), "-") -> 0.96721311 | R21: =IFERROR(M21/(G21+L21), "-") -> 0.96721311
B22: Altamira | C22: =Altamira!F2 -> 40 | D22: =Altamira!F3 -> 358 | E22: =Altamira!H1 -> 5 | F22: =Altamira!H2 -> 46 | G22: =C22-E22 -> 35 | H22: =D22-F22 -> 312 | I22: =Altamira!F4 -> 35 | J22: =Altamira!F5 -> 312 | K22: =Altamira!H3 -> 30 | M22: =K22+L22 -> 30 | N22: =Altamira!H4 -> 203 | P22: =Altamira!H5 -> 5 | Q22: =IFERROR(M22/(I22+L22), "-") -> 0.85714286 | R22: =IFERROR(M22/(G22+L22), "-") -> 0.85714286
B23: Naranjos-Cerro A | C23: ='Naranjos-Cerro A'!F2 -> 29 | D23: ='Naranjos-Cerro A'!F3 -> 245 | E23: ='Naranjos-Cerro A'!H1 -> 5 | F23: ='Naranjos-Cerro A'!H2 -> 43 | G23: =C23-E23 -> 24 | H23: =D23-F23 -> 202 | I23: ='Naranjos-Cerro A'!F4 -> 24 | J23: ='Naranjos-Cerro A'!F5 -> 202 | K23: ='Naranjos-Cerro A'!H3 -> 20 | M23: =K23+L23 -> 20 | N23: ='Naranjos-Cerro A'!H4 -> 138 | P23: ='Naranjos-Cerro A'!H5 -> 4 | Q23: =IFERROR(M23/(I23+L23), "-") -> 0.83333333 | R23: =IFERROR(M23/(G23+L23), "-") -> 0.83333333
B24: Poza Rica | C24: ='Poza Rica'!F2 -> 64 | D24: ='Poza Rica'!F3 -> 509 | E24: ='Poza Rica'!H1 -> 18 | F24: ='Poza Rica'!H2 -> 135 | G24: =C24-E24 -> 46 | H24: =D24-F24 -> 374 | I24: ='Poza Rica'!F4 -> 46 | J24: ='Poza Rica'!F5 -> 374 | K24: ='Poza Rica'!H3 -> 29 | M24: =K24+L24 -> 29 | N24: ='Poza Rica'!H4 -> 194 | P24: ='Poza Rica'!H5 -> 17 | Q24: =IFERROR(M24/(I24+L24), "-") -> 0.63043478 | R24: =IFERROR(M24/(G24+L24), "-") -> 0.63043478
B25: Veracruz | C25: =Veracruz!F2 -> 40 | D25: =Veracruz!F3 -> 181 | E25: =Veracruz!H1 -> 3 | F25: =Veracruz!H2 -> 24 | G25: =C25-E25 -> 37 | H25: =D25-F25 -> 157 | I25: =Veracruz!F4 -> 37 | J25: =Veracruz!F5 -> 157 | K25: =Veracruz!H3 -> 34 | M25: =K25+L25 -> 34 | N25: =Veracruz!H4 -> 103 | P25: =Veracruz!H5 -> 3 | Q25: =IFERROR(M25/(I25+L25), "-") -> 0.91891892 | R25: =IFERROR(M25/(G25+L25), "-") -> 0.91891892
B26: Norte | C26: =SUM(C21:C25) -> 229 | D26: =SUM(D21:D25) -> 1879 | E26: =SUM(E21:E25) -> 31 | F26: =SUM(F21:F25) -> 248 | G26: =SUM(G21:G25) -> 198 | H26: =SUM(H21:H25) -> 1631 | I26: =SUM(I21:I25) -> 198 | J26: =SUM(J21:J25) -> 1631 | ... L26: =SUM(L21:L25) -> 5 | M26: =K26+L26 -> 172 | N26: =SUM(N21:N25) -> 1135 | O26: =SUM(O21:O25) -> 42 | P26: =SUM(P21:P25) -> 31 | Q26: =IFERROR(M26/(I26+L26), "-") -> 0.84729064 | R26: =IFERROR(M26/(G26+L26), "-") -> 0.84729064
I29: Periodo
C30: PICADE Autorizado | E30: Vencidos antes de PICADE | G30: PICADE Ajustado con LN | I30: 19 de abril al | L30: =CONCATENATE(TEXT(T3, "dd"), " de ", TEXT(T3, "mmmm")," de ",TEXT(T3,"aaaa")) -> 31 de diciembre de 2021
B31: Región Sur | C31: Cursos | D31: Capacitandos | E31: Cursos | F31: Capacitandos | G31: Cursos | H31: Capacitandos | I31: Programados | J31: Capacitandos | K31: Realizados en prog. | L31: Adicionales | M31: Realizados | N31: Capacitandos | O31: Capacitandos Adicionales | P31: Cancelados | Q31: Cumplimiento en el periodo (%) | R31: Avance del PICADE ajustado (%)
B32: Cinco Presidentes | C32: ='Cinco Presidentes'!F2 -> 109 | D32: ='Cinco Presidentes'!F3 -> 1301 | E32: ='Cinco Presidentes'!H1 -> 4 | F32: ='Cinco Presidentes'!H2 -> 27 | G32: ='Cinco Presidentes'!L4 -> 66 | H32: ='Cinco Presidentes'!L3 -> 849 | I32: ='Cinco Presidentes'!F4 -> 66 | J32: ='Cinco Presidentes'!F5 -> 849 | K32: ='Cinco Presidentes'!H3 -> 18 | L32: 11 | M32: =K32+L32 -> 29 | N32: ='Cinco Presidentes'!H4 -> 172 | O32: 52 | P32: ='Cinco Presidentes'!H5 -> 79 | Q32: =IFERROR(M32/(I32+L32), "-") -> 0.37662338 | R32: =IFERROR(M32/(G32+L32), "-") -> 0.37662338
B33: Bellota Jujo | C33: ='Bellota Jujo'!F2 -> 41 | D33: ='Bellota Jujo'!F3 -> 627 | E33: ='Bellota Jujo'!H1 -> 3 | F33: ='Bellota Jujo'!H2 -> 51 | G33: ='Bellota Jujo'!L3 -> 28 | H33: ='Bellota Jujo'!L4 -> 455 | I33: ='Bellota Jujo'!F4 -> 28 | J33: ='Bellota Jujo'!F5 -> 455 | K33: ='Bellota Jujo'!H3 -> 17 | L33: 7 | M33: =K33+L33 -> 24 | N33: ='Bellota Jujo'!H4 -> 160 | O33: 8 | P33: ='Bellota Jujo'!H5 -> 11 | Q33: =IFERROR(M33/(I33+L33), "-") -> 0.68571429 | R33: =IFERROR(M33/(G33+L33), "-") -> 0.68571429
B34: Macuspana | C34: =Macuspana!F2 -> 55 | D34: =Macuspana!F3 -> 622 | E34: =Macuspana!H1 -> 8 | F34: =Macuspana!H2 -> 95 | G34: =Macuspana!L4 -> 16 | H34: =Macuspana!L3 -> 211 | I34: =Macuspana!F4 -> 16 | J34: =Macuspana!F5 -> 211 | K34: =Macuspana!H3 -> 12 | L34: 7 | M34: =K34+L34 -> 19 | N34: =Macuspana!H4 -> 81 | O34: 12 | P34: =Macuspana!H5 -> 12 | Q34: =IFERROR(M34/(I34+L34), "-") -> 0.82608696 | R34: =IFERROR(M34/(G34+L34), "-") -> 0.82608696
B35: Samaria Luna | C35: ='Samaria Luna'!F2 -> 30 | D35: ='Samaria Luna'!F3 -> 296 | E35: ='Samaria Luna'!H1 -> 7 | F35: ='Samaria Luna'!H2 -> 76 | G35: ='Samaria Luna'!L4 -> 21 | H35: ='Samaria Luna'!L3 -> 211 | I35: ='Samaria Luna'!F4 -> 21 | J35: ='Samaria Luna'!F5 -> 211 | K35: ='Samaria Luna'!H3 -> 17 | L35: 1 | M35: =K35+L35 -> 18 | N35: ='Samaria Luna'!H4 -> 119 | O35: 9 | P35: ='Samaria Luna'!H5 -> 4 | Q35: =IFERROR(M35/(I35+L35), "-") -> 0.81818182 | R35: =IFERROR(M35/(G35+L35), "-") -> 0.81818182
B36: Villahermosa | C36: =Villahermosa!F2 -> 22 | D36: =Villahermosa!F3 -> 169 | E36: =Villahermosa!H1 -> 5 | F36: =Villahermosa!H2 -> 16 | G36: =Villahermosa!L4 -> 8 | H36: =Villahermosa!L3 -> 75 | I36: =Villahermosa!F4 -> 8 | J36: =Villahermosa!F5 -> 75 | K36: =Villahermosa!H3 -> 5 | L36: 2 | M36: =K36+L36 -> 7 | N36: =Villahermosa!H4 -> 53 | O36: 23 | P36: 14 | Q36: =IFERROR(M36/(I36+L36), "-") -> 0.7 | R36: =IFERROR(M36/(G36+L36), "-") -> 0.7
B37: Sur | C37: =SUM(C32:C36) -> 257 | D37: =SUM(D32:D36) -> 3015 | E37: =SUM(E32:E36) -> 27 | F37: =SUM(F32:F36) -> 265 | G37: =SUM(G32:G36) -> 139 | H37: =SUM(H32:H36) -> 1801 | I37: =SUM(I32:I36) -> 139 | J37: =SUM(J32:J36) -> 1801 | ... L37: =SUM(L32:L36) -> 28 | M37: =K37+L37 -> 97 | N37: =SUM(N32:N36) -> 585 | O37: =SUM(O32:O36) -> 104 | P37: =SUM(P32:P36) -> 120 | Q37: =IFERROR(M37/(I37+L37), "-") -> 0.58083832 | R37: =IFERROR(M37/(G37+L37), "-") -> 0.58083832
I40: Periodo
C41: PICADE Autorizado | E41: Vencidos antes de PICADE | G41: PICADE Ajustado con LN | I41: 19 de abril al | L41: =CONCATENATE(TEXT(T3, "dd"), " de ", TEXT(T3, "mmmm")," de ",TEXT(T3,"aaaa")) -> 31 de diciembre de 2021
B42: Subdirección | C42: Cursos | D42: Capacitandos | E42: Cursos | F42: Capacitandos | G42: Cursos | H42: Capacitandos | I42: Programados | J42: Capacitandos | K42: Realizados en prog. | L42: Adicionales | M42: Realizados | N42: Capacitandos | O42: Capacitandos Adicionales | P42: Cancelados | Q42: Cumplimiento en el periodo (%) | R42: Avance del PICADE ajustado (%)
B43: SPRN | C43: =COUNTIF(Reynosa!$E$8:$E$63,"Subdirección de Producción Región Norte")+COUNTIF(Altamira!$E$8:$E$47,"Subdirección de Producción Región Norte")+COUNTIF('Naranjos-Cerro A'!$E$8:$E$36,"Subdirección de Producción Región Norte")+COUNTIF('Poza Rica'!$E$8:$E$71,"Subdirección de Producción Región Norte")+COUNTIF(Veracruz!$E$8:$E$47,"Subdirección de Producción Región Norte") -> 104 | D43: =SUMIF(Reynosa!$E$8:$E$63,"Subdirección de Producción Región Norte",Reynosa!$M$8:$M$63)+SUMIF(Altamira!$E$8:$E$47,"Subdirección de Producción Región Norte",Altamira!$M$8:$M$47)+SUMIF('Naranjos-Cerro A'!$E$8:$E$36,"Subdirección de Producción Región Norte",'Naranjos-Cerro A'!$M$8:$M$36)+SUMIF('Poza Rica'!$E$8:$E$71,"Subdirección de Producción Región Norte",'Poza Rica'!$M$8:$M$71)+SUMIF(Veracruz!$E$8:$E$47,"Subdirección de Producción Región Norte",Veracruz!$M$8:$M$47) -> 956 | E43: =COUNTIF(Altamira!$E$8:$E$12,"Subdirección de Producción Región Norte")+COUNTIF('Naranjos-Cerro A'!$E$8:$E$12,"Subdirección de Producción Región Norte")+COUNTIF('Poza Rica'!$E$8:$E$25,"Subdirección de Producción Región Norte")+COUNTIF(Veracruz!$E$5:$E$10,"Subdirección de Producción Región Norte") -> 15 | F43: =SUMIF(Altamira!$E$8:$E$12,"Subdirección de Producción Región Norte",Altamira!$M$8:$M$12)+SUMIF('Naranjos-Cerro A'!$E$8:$E$12,"Subdirección de Producción Región Norte",'Naranjos-Cerro A'!$M$8:$M$12)+SUMIF('Poza Rica'!$E$8:$E$25,"Subdirección de Producción Región Norte",'Poza Rica'!$M$8:$M$25)+SUMIF(Veracruz!$E$5:$E$10,"Subdirección de Producción Región Norte",Veracruz!$M$5:$M$10) -> 133 | G43: =COUNTIF(Reynosa!$E$8:$E$63,"Subdirección de Producción Región Norte")+COUNTIF(Altamira!$E$13:$E$47,"Subdirección de Producción Región Norte")+COUNTIF('Naranjos-Cerro A'!$E$13:$E$36,"Subdirección de Producción Región Norte")+COUNTIF('Poza Rica'!$E$26:$E$71,"Subdirección de Producción Región Norte")+COUNTIF(Veracruz!$E$11:$E$47,"Subdirección de Producción Región Norte") -> 89 | H43: =SUMIF(Reynosa!$E$8:$E$63,"Subdirección de Producción Región Norte",Reynosa!$M$8:$M$63)+SUMIF(Altamira!$E$13:$E$47,"Subdirección de Producción Región Norte",Altamira!$M$13:$M$47)+SUMIF('Naranjos-Cerro A'!$E$14:$E$36,"Subdirección de Producción Región Norte",'Naranjos-Cerro A'!$M$14:$M$36)+SUMIF('Poza Rica'!$E$26:$E$71,"Subdirección de Producción Región Norte",'Poza Rica'!$M$26:$M$71)+SUMIF(Veracruz!$E$11:$E$47,"Subdirección de Producción Región Norte",Veracruz!$M$11:$M$47) -> 823 | I43: =COUNTIFS(Reynosa!$E$8:$E$63,"Subdirección de Producción Región Norte",Reynosa!$Q$8:$Q$63,"1")+COUNTIFS(Altamira!$E$13:$E$47,"Subdirección de Producción Región Norte",Altamira!$Q$13:$Q$47,"1")+COUNTIFS('Naranjos-Cerro A'!$E$13:$E$36,"Subdirección de Producción Región Norte",'Naranjos-Cerro A'!$Q$13:$Q$36,"1")+COUNTIFS('Poza Rica'!$E$26:$E$71,"Subdirección de Producción Región Norte",'Poza Rica'!$Q$26:$Q$71,"1")+COUNTIFS(Veracruz!$E$11:$E$47,"Subdirección de Producción Región Norte",Veracruz!$Q$11:$Q$47,"1") -> 89 | J43: =SUMIFS(Reynosa!$M$8:$M$63,Reynosa!$E$8:$E$63,"Subdirección de Producción Región Norte",Reynosa!$Q$8:$Q$63,"1")+SUMIFS(Altamira!$M$13:$M$47,Altamira!$E$13:$E$47,"Subdirección de Producción Región Norte",Altamira!$Q$13:$Q$47,"1")+SUMIFS('Naranjos-Cerro A'!$M$14:$M$36,'Naranjos-Cerro A'!$E$14:$E36,"Subdirección de Producción Región Norte",'Naranjos-Cerro A'!$Q$14:$Q$36,"1")+SUMIFS('Poza Rica'!$M$26:$M$71,'Poza Rica'!$E$26:$E$71,"Subdirección de Producción Región Norte",'Poza Rica'!$Q$26:$Q$71,"1")+SUMIFS(Veracruz!$M$11:$M$47,Veracruz!$E$11:$E$47,"Subdirección de Producción Región Norte",Veracruz!$Q$11:$Q$47,"1") -> 823 | K43: =COUNTIFS(Reynosa!$E$8:$E$63,"Subdirección de Producción Región Norte",Reynosa!$Q$8:$Q$63,"1",Reynosa!$R$8:$R$63,"Realizado")+COUNTIFS(Altamira!$E$13:$E$47,"Subdirección de Producción Región Norte",Altamira!$Q$13:$Q$47,"1",Altamira!$R$13:$R$47,"Realizado")+COUNTIFS('Naranjos-Cerro A'!$E$13:$E$36,"Subdirección de Producción Región Norte",'Naranjos-Cerro A'!$Q$13:$Q$36,"1",'Naranjos-Cerro A'!$R$13:$R$36,"Realizado")+COUNTIFS('Poza Rica'!$E$26:$E$71,"Subdirección de Producción Región Norte",'Poza Rica'!$Q$26:$Q$71,"1",'Poza Rica'!$R$26:$R$71,"Realizado")+COUNTIFS(Veracruz!$E$11:$E$47,"Subdirección de Producción Región Norte",Veracruz!$Q$11:$Q$47,"1",Veracruz!$R$11:$R$47,"Realizado") -> 77 | L43: =COUNTIF(Adicionales!$E$9:$E$88,"Subdirección de Producción Región Norte") -> 1 | M43: =K43+L43 -> 78 | N43: =SUMIFS(Reynosa!$S$8:$S$63,Reynosa!$E$8:$E$63,"Subdirección de Producción Región Norte",Reynosa!$Q$8:$Q$63,"1",Reynosa!$R$8:$R$63,"Realizado")+SUMIFS(Altamira!$S$13:$S$47,Altamira!$E$13:$E$47,"Subdirección de Producción Región Norte",Altamira!$Q$13:$Q$47,"1",Altamira!$R$13:$R$47,"Realizado")+SUMIFS('Naranjos-Cerro A'!$S$13:$S$36,'Naranjos-Cerro A'!$E$13:$E36,"Subdirección de Producción Región Norte",'Naranjos-Cerro A'!$Q$13:$Q$36,"1",'Naranjos-Cerro A'!$R$13:$R$36,"Realizado")+SUMIFS('Poza Rica'!$S$26:$S$71,'Poza Rica'!$E$26:$E$71,"Subdirección de Producción Región Norte",'Poza Rica'!$Q$26:$Q$71,"1",'Poza Rica'!$R$26:$R$71,"Realizado")+SUMIFS(Veracruz!$S$11:$S$47,Veracruz!$E$11:$E$47,"Subdirección de Producción Región Norte",Veracruz!$Q$11:$Q$47,"1",Veracruz!$R$11:$R$47,"Realizado") -> 579 | O43: =SUMIF(Adicionales!$E$9:$E$86,"Subdirección de Producción Región Norte",Adicionales!$M$9:$M$86) -> 17 | P43: =COUNTIFS(Reynosa!$E$8:$E$63,"Subdirección de Producción Región Norte",Reynosa!$Q$8:$Q$63,"1",Reynosa!$R$8:$R$63,"cancelado")+COUNTIFS(Altamira!$E$13:$E$47,"Subdirección de Producción Región Norte",Altamira!$Q$13:$Q$47,"1",Altamira!$R$13:$R$47,"Cancelado")+COUNTIFS('Naranjos-Cerro A'!$E$14:$E$36,"Subdirección de Producción Región Norte",'Naranjos-Cerro A'!$Q$14:$Q$36,"1",'Naranjos-Cerro A'!$R$14:$R$36,"Cancelado")+COUNTIFS('Poza Rica'!$E$26:$E$71,"Subdirección de Producción Región Norte",'Poza Rica'!$Q$26:$Q$71,"1",'Poza Rica'!$R$26:$R$71,"Cancelado")+COUNTIFS(Veracruz!$E$11:$E$47,"Subdirección de Producción Región Norte",Veracruz!$Q$11:$Q$47,"1",Veracruz!$R$11:$R$47,"Cancelado") -> 12 | Q43: =IFERROR(M43/(I43+L43), "-") -> 0.86666667 | R43: =IFERROR(M43/(G43+L43), "-") -> 0.86666667
B44: SPRMSO | C44: =COUNTIF('Dos Bocas'!$F$8:$F$195,"Subdirección de Producción Región Marina Suroeste") -> 17 | D44: =SUMIF('Dos Bocas'!$F$8:$F$195,"Subdirección de Producción Región Marina Suroeste",'Dos Bocas'!$N$8:$N$195) -> 198 | E44: =COUNTIF('Dos Bocas'!$F$8:$F$10,"Subdirección de Producción Región Marina Suroeste") -> 2 | F44: =SUMIF('Dos Bocas'!$F$8:$F$10,"Subdirección de Producción Región Marina Suroeste",'Dos Bocas'!$Q$8:$Q$10) -> 19 | G44: =COUNTIF('Dos Bocas'!$F$108:$F$195,"Subdirección de Producción Región Marina Suroeste") -> 14 | H44: =SUMIF('Dos Bocas'!$F$108:$F$195,"Subdirección de Producción Región Marina Suroeste",'Dos Bocas'!$Q$108:$Q$195) -> 170 | I44: =COUNTIFS('Dos Bocas'!$F$108:$F$195,"Subdirección de Producción Región Marina Suroeste",'Dos Bocas'!$U$108:$U$195,"1") -> 14 | J44: =SUMIFS('Dos Bocas'!$Q$108:$Q$195,'Dos Bocas'!$F$108:$F$195,"Subdirección de Producción Región Marina Suroeste",'Dos Bocas'!$U$108:$U$195,"1") -> 170 | K44: =COUNTIFS('Dos Bocas'!$F$94:$F$195,"Subdirección de Producción Región Marina Suroeste",'Dos Bocas'!$U$94:$U$195,"1",'Dos Bocas'!$V$94:$V$195,"Realizado") -> 13 | L44: =COUNTIF(Adicionales!$E$9:$E$86,"Subdirección de Producción Región Marina Suroeste") -> 14 | M44: =K44+L44 -> 27 | N44: =SUMIFS('Dos Bocas'!$W$94:$W$195,'Dos Bocas'!$F$94:$F$195,"Subdirección de Producción Región Marina Suroeste",'Dos Bocas'!$U$94:$U$195,"1",'Dos Bocas'!$V$94:$V$195,"Realizado") -> 157 | O44: =SUMIF(Adicionales!$E$9:$E$86,"Subdirección de Producción Región Marina Suroeste",Adicionales!$M$9:$M$86) -> 187 | P44: =COUNTIFS('Dos Bocas'!$F$108:$F$195,"Subdirección de Producción Región Marina Suroeste",'Dos Bocas'!$U$108:$U$195,"1",'Dos Bocas'!$V$108:$V$195,"Cancelado") -> 2 | Q44: =IFERROR(M44/(I44+L44), "-") -> 0.96428571 | R44: =IFERROR(M44/(G44+L44), "-") -> 0.96428571
B45: SPRMNE | C45: =COUNTIF('Cd. Carmen'!$E$8:$E$190,"Subdirección de Producción Región Marina Noreste") -> 65 | D45: =SUMIF('Cd. Carmen'!$E$8:$E$190,"Subdirección de Producción Región Marina Noreste",'Cd. Carmen'!$M$8:$M$190) -> 1046 | E45: =COUNTIF('Cd. Carmen'!$E$8:$E$26,"Subdirección de Producción Región Marina Noreste") -> 0 | F45: =SUMIF('Cd. Carmen'!$E$8:$E$27,"Subdirección de Producción Región Marina Noreste",'Cd. Carmen'!$M$8:$M$27) -> 0 | G45: =COUNTIF('Cd. Carmen'!$E$27:$E$190,"Subdirección de Producción Región Marina Noreste") -> 65 | H45: =SUMIF('Cd. Carmen'!$E$27:$E$190,"Subdirección de Producción Región Marina Noreste",'Cd. Carmen'!$M$27:$M$190) -> 1046 | I45: =COUNTIFS('Cd. Carmen'!$E$27:$E$190,"Subdirección de Producción Región Marina Noreste",'Cd. Carmen'!$Q$27:$Q$190,"1") -> 65 | J45: =SUMIFS('Cd. Carmen'!$M$27:$M$190,'Cd. Carmen'!$E$27:$E$190,"Subdirección de Producción Región Marina Noreste",'Cd. Carmen'!$Q$27:$Q$190,"1") -> 1046 | K45: =COUNTIFS('Cd. Carmen'!$E$25:$E$190,"Subdirección de Producción Región Marina Noreste",'Cd. Carmen'!$Q$25:$Q$190,"1",'Cd. Carmen'!$R$25:$R$190,"Realizado") -> 20 | L45: =COUNTIF(Adicionales!$E$9:$E$86,"Subdirección de Producción Región Marina Noreste") -> 3 | M45: =K45+L45 -> 23 | N45: =SUMIFS('Cd. Carmen'!$S$25:$S$190,'Cd. Carmen'!$E$25:$E$190,"Subdirección de Producción Región Marina Noreste",'Cd. Carmen'!$Q$25:$Q$190,"1",'Cd. Carmen'!$R$25:$R$190,"Realizado") -> 212 | O45: =SUMIF(Adicionales!$E$9:$E$86,"Subdirección de Producción Región Marina Noreste",Adicionales!$M$9:$M$86) -> 40 | P45: =COUNTIFS('Cd. Carmen'!$E$25:$E$190,"Subdirección de Producción Región Marina Noreste",'Cd. Carmen'!$Q$25:$Q$190,"1",'Cd. Carmen'!$R$25:$R$190,"Cancelado") -> 45 | Q45: =IFERROR(M45/(I45+L45), "-") -> 0.33823529 | R45: =IFERROR(M45/(G45+L45), "-") -> 0.33823529
B46: SCOC | C46: =COUNTIF('Dos Bocas'!$F$8:$F$195,"Subdirección de Coordinación Operativa y Comercial")+COUNTIF('Cd. Carmen'!$E$8:$E$190,"Subdirección de Coordinación Operativa y Comercial")+COUNTIF('Cd. Méx'!$E$8:$E$11,"Subdirección de Coordinación Operativa y Comercial") -> 173 | D46: =SUMIF('Dos Bocas'!$F$8:$F$195,"Subdirección de Coordinación Operativa y Comercial",'Dos Bocas'!$N$8:$N$195)+SUMIF('Cd. Carmen'!$E$8:$E$190,"Subdirección de Coordinación Operativa y Comercial",'Cd. Carmen'!$M$8:$M$190)+SUMIF('Cd. Méx'!$E$8:$E$11,"Subdirección de Coordinación Operativa y Comercial",'Cd. Méx'!$M$8:$M$11) -> 776 | E46: =COUNTIF('Cd. Carmen'!$E$8:$E$26,"Subdirección de Coordinación Operativa y Comercial")+COUNTIF('Dos Bocas'!$F$8:$F$10,"Subdirección de Coordinación Operativa y Comercial") -> 0 | F46: =SUMIF('Cd. Carmen'!$E$8:$E$27,"Subdirección de Coordinación Operativa y Comercial",'Cd. Carmen'!$M$8:$M$27)+SUMIF('Dos Bocas'!$F$8:$F$10,"Subdirección de Coordinación Operativa y Comercial",'Dos Bocas'!$Q$8:$Q$10) -> 0 | G46: =COUNTIF('Dos Bocas'!$F$108:$F$195,"Subdirección de Coordinación Operativa y Comercial")+COUNTIF('Cd. Carmen'!$E$27:$E$190,"Subdirección de Coordinación Operativa y Comercial") -> 76 | H46: =SUMIF('Cd. Carmen'!$E$27:$E$190,"Subdirección de Coordinación Operativa y Comercial",'Cd. Carmen'!$M$27:$M$190)+SUMIF('Dos Bocas'!$F$108:$F$195,"Subdirección de Coordinación Operativa y Comercial",'Dos Bocas'!$Q$108:$Q$195) -> 677 | I46: =COUNTIFS('Cd. Carmen'!$E$27:$E$190,"Subdirección de Coordinación Operativa y Comercial",'Cd. Carmen'!$Q$27:$Q$190,"1")+COUNTIFS('Dos Bocas'!$F$108:$F$195,"Subdirección de Coordinación Operativa y Comercial",'Dos Bocas'!$U$108:$U$195,"1") -> 76 | J46: =SUMIFS('Dos Bocas'!$Q$108:$Q$195,'Dos Bocas'!$F$108:$F$195,"Subdirección de Coordinación Operativa y Comercial",'Dos Bocas'!$U$108:$U$195,"1")+SUMIFS('Cd. Carmen'!$M$27:$M$190,'Cd. Carmen'!$E$27:$E$190,"Subdirección de Coordinación Operativa y Comercial",'Cd. Carmen'!$Q$27:$Q$190,"1") -> 677 | K46: =COUNTIFS('Cd. Carmen'!$E$25:$E$190,"Subdirección de Coordinación Operativa y Comercial",'Cd. Carmen'!$Q$25:$Q$190,"1",'Cd. Carmen'!$R$25:$R$190,"Realizado")+COUNTIFS('Dos Bocas'!$F$94:$F$195,"Subdirección de Coordinación Operativa y Comercial",'Dos Bocas'!$U$94:$U$195,"1",'Dos Bocas'!$V$94:$V$195,"Realizado") -> 63 | L46: =COUNTIF(Adicionales!$E$9:$E$86,"Subdirección de Coordinación Operativa y Comercial") -> 2 | M46: =K46+L46 -> 65 | N46: =SUMIFS('Cd. Carmen'!$S$25:$S$190,'Cd. Carmen'!$E$25:$E$190,"Subdirección de Coordinación Operativa y Comercial",'Cd. Carmen'!$Q$25:$Q$190,"1",'Cd. Carmen'!$S$25:$S$190,"Realizado")+SUMIFS('Dos Bocas'!$W$94:$W$195,'Dos Bocas'!$F$94:$F$195,"Subdirección de Coordinación Operativa y Comercial",'Dos Bocas'!$U$94:$U$195,"1",'Dos Bocas'!$V$94:$V$195,"Realizado") -> 438 | O46: =SUMIF(Adicionales!$E$9:$E$86,"Subdirección de Coordinación Operativa y Comercial",Adicionales!$M$9:$M$86) -> 15 | P46: =COUNTIFS('Cd. Carmen'!$E$25:$E$190,"Subdirección de Coordinación Operativa y Comercial",'Cd. Carmen'!$Q$25:$Q$190,"1",'Cd. Carmen'!$R$25:$R$190,"Cancelado")+COUNTIFS('Dos Bocas'!$F$108:$F$195,"Subdirección de Coordinación Operativa y Comercial",'Dos Bocas'!$V$108:$V$195,"Cancelado") -> 13 | Q46: =IFERROR(M46/(I46+L46), "-") -> 0.83333333 | R46: =IFERROR(M46/(G46+L46), "-") -> 0.83333333
B47: SPRS | C47: =COUNTIF('Cinco Presidentes'!$E$8:$E$116,"Subdirección de Producción Región Sur")+COUNTIF('Bellota Jujo'!$E$8:$E$48,"Subdirección de Producción Región Sur")+COUNTIF(Macuspana!$E$8:$E$67,"Subdirección de Producción Región Sur")+COUNTIF('Samaria Luna'!$E$8:$E$37,"Subdirección de Producción Región Sur")+COUNTIF(Villahermosa!$E$8:$E$29,"Subdirección de Producción Región Sur") -> 230 | D47: =SUMIF('Cinco Presidentes'!$E$8:$E$116,"Subdirección de Producción Región Sur",'Cinco Presidentes'!$M$8:$M$116)+SUMIF('Bellota Jujo'!$E$8:$E$48,"Subdirección de Producción Región Sur",'Bellota Jujo'!$M$8:$M$48)+SUMIF(Macuspana!$E$8:$E$67,"Subdirección de Producción Región Sur",Macuspana!$M$8:$M$67)+SUMIF('Samaria Luna'!$E$8:$E$37,"Subdirección de Producción Región Sur",'Samaria Luna'!$M$8:$M$37)+SUMIF(Villahermosa!$E$8:$E$29,"Subdirección de Producción Región Sur",Villahermosa!$M$8:$M$29) -> 2814 | E47: =COUNTIF('Cinco Presidentes'!$E$8:$E$11,"Subdirección de Producción Región Sur")+COUNTIF('Bellota Jujo'!$E$8:$E$10,"Subdirección de Producción Región Sur")+COUNTIF(Macuspana!$E$8:$E$15,"Subdirección de Producción Región Sur")+COUNTIF('Samaria Luna'!$E$8:E14,"Subdirección de Producción Región Sur")+COUNTIF(Villahermosa!$E$8:$E$12,"Subdirección de Producción Región Sur") -> 25 | F47: =SUMIF('Cinco Presidentes'!$E$8:$E$11,"Subdirección de Producción Región Sur",'Cinco Presidentes'!$M$8:$M$11)+SUMIF('Bellota Jujo'!$E$8:$E$10,"Subdirección de Producción Región Sur",'Bellota Jujo'!$M$8:$M$10)+SUMIF(Macuspana!$E$8:$E$15,"Subdirección de Producción Región Sur",Macuspana!$M$8:$M$15)+SUMIF('Samaria Luna'!$E$8:$E$14,"Subdirección de Producción Región Sur",'Samaria Luna'!$M$8:$M$14)+SUMIF(Villahermosa!$E$8:$E$12,"Subdirección de Producción Región Sur",Villahermosa!$M$8:$M$12) -> 258 | G47: =COUNTIF('Cinco Presidentes'!$E$51:$E$116,"Subdirección de Producción Región Sur")+COUNTIF('Bellota Jujo'!$E$21:$E$48,"Subdirección de Producción Región Sur")+COUNTIF(Macuspana!$E$47:$E$67,"Subdirección de Producción Región Sur")+COUNTIF('Samaria Luna'!$E$17:$E$37,"Subdirección de Producción Región Sur")+COUNTIF(Villahermosa!$E$22:$E$29,"Subdirección de Producción Región Sur") -> 123 | H47: =SUMIF('Cinco Presidentes'!$E$51:$E$116,"Subdirección de Producción Región Sur",'Cinco Presidentes'!$M$51:$M$116)+SUMIF('Bellota Jujo'!$E$21:$E$48,"Subdirección de Producción Región Sur",'Bellota Jujo'!$M$21:$M$48)+SUMIF(Macuspana!$E$47:$E$67,"Subdirección de Producción Región Sur",Macuspana!$M$47:$M$67)+SUMIF('Samaria Luna'!$E$17:$E$37,"Subdirección de Producción Región Sur",'Samaria Luna'!$M$17:$M$37)+SUMIF(Villahermosa!$E$22:$E$29,"Subdirección de Producción Región Sur",Villahermosa!$M$22:$M$29) -> 1649 | I47: =COUNTIFS('Cinco Presidentes'!$E$51:$E$116,"Subdirección de Producción Región Sur",'Cinco Presidentes'!$Q$51:$Q$116,"1")+COUNTIFS('Bellota Jujo'!$E$21:$E$48,"Subdirección de Producción Región Sur",'Bellota Jujo'!$Q$21:$Q$48,"1")+COUNTIFS(Macuspana!$E$47:$E$67,"Subdirección de Producción Región Sur",Macuspana!$Q$47:$Q$67,"1")+COUNTIFS('Samaria Luna'!$E$17:$E$37,"Subdirección de Producción Región Sur",'Samaria Luna'!$Q$17:$Q$37,"1")+COUNTIFS(Villahermosa!$E$22:$E$29,"Subdirección de Producción Región Sur",Villahermosa!$Q$22:$Q$29,"1") -> 123 | J47: =SUMIFS('Cinco Presidentes'!$M$51:$M$116,'Cinco Presidentes'!$E$51:$E$116,"Subdirección de Producción Región Sur",'Cinco Presidentes'!$Q$51:$Q$116,"1")+SUMIFS('Bellota Jujo'!$M$21:$M$48,'Bellota Jujo'!$E$21:$E$48,"Subdirección de Producción Región Sur",'Bellota Jujo'!$Q$21:$Q$48,"1")+SUMIFS(Macuspana!$M$47:$M$67,Macuspana!$E$47:$E$67,"Subdirección de Producción Región Sur",Macuspana!$Q$47:$Q$67,"1")+SUMIFS('Samaria Luna'!$M$17:$M$37,'Samaria Luna'!$E$17:$E$37,"Subdirección de Producción Región Sur",'Samaria Luna'!$Q$17:$Q$37,"1")+SUMIFS(Villahermosa!$M$22:$M$29,Villahermosa!$E$22:$E$29,"Subdirección de Producción Región Sur",Villahermosa!$Q$22:$Q$29,"1") -> 1649 | K47: =COUNTIFS('Cinco Presidentes'!$E$10:$E$116,"Subdirección de Producción Región Sur",'Cinco Presidentes'!$Q$10:$Q$116,"1",'Cinco Presidentes'!$R$10:$R$116,"Realizado")+COUNTIFS('Bellota Jujo'!$E$21:$E$48,"Subdirección de Producción Región Sur",'Bellota Jujo'!$Q$21:$Q$48,"1",'Bellota Jujo'!$R$21:$R$48,"Realizado")+COUNTIFS(Macuspana!$E$37:$E$62,"Subdirección de Producción Región Sur",Macuspana!$Q$37:$Q$62,"1",Macuspana!$R$37:$R$62,"Realizado")+COUNTIFS('Samaria Luna'!$E$17:$E$37,"Subdirección de Producción Región Sur",'Samaria Luna'!$Q$17:$Q$37,"1",'Samaria Luna'!$R$17:$R$37,"Realizado")+COUNTIFS(Villahermosa!$E$22:$E$29,"Subdirección de Producción Región Sur",Villahermosa!$Q$22:$Q$29,"1",Villahermosa!$R$22:$R$29,"Realizdo")+1 -> 62 | L47: =COUNTIF(Adicionales!$E$9:$E$88,"Subdirección de Producción Región Sur") -> 8 | M47: =K47+L47 -> 70 | N47: =SUMIFS('Cinco Presidentes'!$S$10:$S$116,'Cinco Presidentes'!$E$10:$E$116,"Subdirección de Producción Región Sur",'Cinco Presidentes'!$Q$10:$Q$116,"1",'Cinco Presidentes'!$R$10:$R$116,"Realizado")+SUMIFS('Bellota Jujo'!$S$21:$S$48,'Bellota Jujo'!$E$21:$E$48,"Subdirección de Producción Región Sur",'Bellota Jujo'!$Q$21:$Q$48,"1",'Bellota Jujo'!$R$21:$R$48,"Realizado")+SUMIFS(Macuspana!$S$37:$S$67,Macuspana!$E$37:$E$67,"Subdirección de Producción Región Sur",Macuspana!$Q$37:$Q$67,"1",Macuspana!$R$37:$R$67,"Realizado")+SUMIFS('Samaria Luna'!$S$17:$S$37,'Samaria Luna'!$E$17:$E$37,"Subdirección de Producción Región Sur",'Samaria Luna'!$Q$17:$Q$37,"1",'Samaria Luna'!$R$17:$R$37,"Realizado")+SUMIFS(Villahermosa!$S$22:$S$29,Villahermosa!$E$22:$E$29,"Subdirección de Producción Región Sur",Villahermosa!$Q$22:$Q$29,"1",Villahermosa!$R$22:$R$29,"Realizado") -> 514 | O47: =SUMIF(Adicionales!$E$9:$E$86,"Subdirección de Producción Región Sur",Adicionales!$M$9:$M$86) -> 69 | P47: =COUNTIFS('Cinco Presidentes'!$E$51:$E$116,"Subdirección de Producción Región Sur",'Cinco Presidentes'!$Q$51:$Q$116,"1",'Cinco Presidentes'!$R$51:$R$116,"Cancelado")+COUNTIFS('Bellota Jujo'!$E$21:$E$48,"Subdirección de Producción Región Sur",'Bellota Jujo'!$Q$21:$Q$48,"1",'Bellota Jujo'!$R$21:$R$48,"Cancelado")+COUNTIFS(Macuspana!$E$47:$E$67,"Subdirección de Producción Región Sur",Macuspana!$Q$47:$Q$67,"1",Macuspana!$R$47:$R$67,"Cancelado")+COUNTIFS('Samaria Luna'!$E$17:$E$37,"Subdirección de Producción Región Sur",'Samaria Luna'!$Q$17:$Q$37,"1",'Samaria Luna'!$R$17:$R$37,"Cancelado")+COUNTIFS(Villahermosa!$E$22:$E$29,"Subdirección de Producción Región Sur",Villahermosa!$Q$22:$Q$29,"1",Villahermosa!$R$22:$R$29,"Cancelado") -> 76 | Q47: =IFERROR(M47/(I47+L47), "-") -> 0.53435115 | R47: =IFERROR(M47/(G47+L47), "-") -> 0.53435115
...

Sheet Cursos
B4: Cursos | C4: Programado
B5: Basico de Seguridad (BS) | C5: =COUNTIF('Dos Bocas'!$H$108:$H$195,Cursos!B5) -> 8
B6: REVALIDACION BASICO DE SEGURIDAD (BS) | C6: =COUNTIF('Dos Bocas'!$H$108:$H$195,Cursos!B6) -> 7
B7: Rig Pass | C7: =COUNTIF('Dos Bocas'!$H$108:$H$195,Cursos!B7) -> 0
B8: Seguridad en Centros Administrativos (SCA) | C8: =COUNTIF('Dos Bocas'!$H$108:$H$195,Cursos!B8) -> 0
B9: Sobrevivencia en el Mar (SM) | C9: =COUNTIF('Dos Bocas'!$H$108:$H$195,Cursos!B9) -> 0
B10: Seguridad y Sobrevivencia en el Mar para Visitas (SSMV) | C10: =COUNTIF('Dos Bocas'!$H$108:$H$195,Cursos!B10) -> 0
B11: SEGURIDAD Y SOBREVIVENCIA COSTA AFUERA (SSCA) | C11: =COUNTIF('Dos Bocas'!$H$108:$H$195,Cursos!B11) -> 13
B12: Revalidacion SEGURIDAD Y SOBREVIVENCIA COSTA AFUERA (RSSCA) | C12: =COUNTIF('Dos Bocas'!$H$108:$H$195,Cursos!B12) -> 0
B13: Liderazgo en SSPA | C13: =COUNTIF('Dos Bocas'!$H$108:$H$195,Cursos!B13) -> 0
B14: Liderazgo Operativo para la Administración de Riesgos | C14: =COUNTIF('Dos Bocas'!$H$108:$H$195,Cursos!B14) -> 0
B15: Planeacion Segura de los Trabajos | C15: =COUNTIF('Dos Bocas'!$H$108:$H$195,Cursos!B15) -> 0
B16: Procedimientos Criticos (PC) | C16: =COUNTIF('Dos Bocas'!$H$108:$H$195,Cursos!B16) -> 6
... B35: Administracion Ambiental | C35: =COUNTIF('Dos Bocas'!$H$108:$H$195,Cursos!B35) -> 1
C36: =SUM(C5:C35) -> 67

Sheet Mensual
B3: Bos Bocas | C3: junio
A4: 24882 | B4: REACREDITACION DE SIGNATARIOS DEL SPPTR (RSPTR) | C4: 03/06/2021
A5: 24516 | B5: BASICO DE SEGURIDAD (BS) | C5: 10/06/2021
A6: 29376 | B6: SEGURIDAD Y SOBREVIVENCIA COSTA AFUERA (SSCA) | C6: 09/06/2021
A7: 25320 | B7: VERIFICADOR DE GAS (VG) | C7: 15/06/2021
A8: 24517 | B8: BASICO DE SEGURIDAD (BS) | C8: 14/06/2021
A9: 31048 | B9: PROCEDIMIENTOS CRITICOS (PC) | C9: 14/06/2021
A10: 24861 | B10: SALUD EN EL TRABAJO | C10: 14/06/2022
A11: 24739 | B11: SISTEMA DE PERMISOS PARA TRABAJOS CON RIESGO (SPTR) | C11: 14/06/2022
A12: 24608 | B12: RESPUESTA A EMERGENCIAS CON MATERIALES PELIGROSOS (REMP) | C12: 24/06/2021
A13: 24740 | B13: SISTEMA DE PERMISOS PARA TRABAJOS CON RIESGO (SPTR) | C13: 28/06/2021
A14: 24639 | B14: BRIGADAS CONTRAINCENDIOS (BCII) | C14: 30/06/2021
B16: Ciudad del Carmen | C16: Junio
A17: 21482 | B17: REACREDITACION DE SIGNATARIOS DEL SPPTR (RSPTR) | C17: 01/06/2021
A18: 21446 | B18: BASICO DE SEGURIDAD (BS) | C18: 02/06/2021
A19: 21447 | B19: BASICO DE SEGURIDAD (BS) | C19: 08/06/2021
A20: 28026 | B20: SOBREVIVENCIA EN EL MAR (SM) | C20: 08/06/2021
A21: 22169 | B21: BRIGADAS DE BUSQUEDA Y RESCATE (BBR) | C21: 09/06/2021
A22: 24591 | B22: SEGURIDAD Y SOBREVIVENCIA COSTA AFUERA (SSCA) | C22: 10/06/2021
A23: 29681 | B23: DISCIPLINA OPERATIVA | C23: 10/06/2021
A24: 24916 | B24: REVALIDACION DE SEGURIDAD Y SOBREVIVENCIA COSTA AFUERA (RSSCA) | C24: 17/06/2021
A25: 27336 | B25: SISTEMA DE PERMISOS PARA TRABAJOS CON RIESGO (SPTR) | C25: 16/06/2021
A26: 21483 | B26: REACREDITACION DE SIGNATARIOS DEL SPPTR (RSPTR) | C26: 21/06/2021
A27: 27337 | B27: SISTEMA DE PERMISOS PARA TRABAJOS CON RIESGO (SPTR) | C27: 19/06/2021
A28: 24592 | B28: SEGURIDAD Y SOBREVIVENCIA COSTA AFUERA (SSCA) | C28: 24/06/2021
... A31: 21432 | B31: REVALIDACION DE SEGURIDAD Y SOBREVIVENCIA COSTA AFUERA (RSSCA) | C31: 29/06/2021
B33: Perforación | C33: Junio
A34: 29104 | B34: BASICO DE SEGURIDAD (BS) | C34: 01/06/2021
A35: 27999 | B35: PLANEACION SEGURA DE LOS TRABAJOS | C35: 01/06/2021
A36: 28003 | B36: PLANEACION SEGURA DE LOS TRABAJOS | C36: 03/06/2021
A37: 29101 | B37: BASICO DE SEGURIDAD (BS) | C37: 03/06/2021
A38: 30822 | B38: BASICO DE SEGURIDAD (BS) | C38: 03/06/2021
A39: 29238 | B39: BRIGADAS DE PRIMEROS AUXILIOS(BPA) | C39: 05/06/2021
A40: 27973 | B40: MANEJO A LA DEFENSIVA (MD) | C40: 07/06/2021
A41: 27974 | B41: MANEJO A LA DEFENSIVA (MD) | C41: 08/06/2021
A42: 29105 | B42: BASICO DE SEGURIDAD (BS) | C42: 08/06/2021
A43: 28001 | B43: PLANEACION SEGURA DE LOS TRABAJOS | C43: 08/06/2021
A44: 28000 | B44: PLANEACION SEGURA DE LOS TRABAJOS | C44: 10/06/2021
A45: 28002 | B45: PLANEACION SEGURA DE LOS TRABAJOS | C45: 14/06/2021
... A54: 23321 | B54: ADMINISTRACION AMBIENTAL | C54: 28/06/2021
...

Sheet Adicionales
F1: Cursos | G1: Capacitandos
E2: Dos Bocas | F2: =COUNTIF(D9:D86,E2) -> 23 | G2: =SUMIF(D9:D74,E2,M9:M86) -> 284
E3: Ciudad del Carmen | F3: =COUNTIF(D9:D86,E3) -> 38 | G3: =SUMIF(D9:D86,E3,M9:M86) -> 398
E4: Sur | F4: =COUNTIF(D9:D109,E4) -> 34 | G4: =SUMIF(D9:D109,E4,M9:M86) -> 310
E5: Norte | F5: =COUNTIF(D9:D86,E5) -> 5 | G5: =SUMIF(D9:D77,E5,M9:M86) -> 42
E6: Perforación | F6: =COUNTIF(D9:D86,E6) -> 1 | G6: =SUMIF(D9:D86,E6,M9:M86) -> 5
A8: Cons | B8: ID_SAP | D8: Cases | E8: Subdirección | F8: Gerencia/Activo | G8: Curso | H8: Tipo de Impartición | I8: Ficha | J8: Instructor | K8: Duración (Horas) | L8: Días | M8: Asistentes Totales | N8: Fecha de Inicio | O8: Fecha de Termino | P8: Observaciones
A9: 1 | B9: 50607931 | D9: Dos Bocas | E9: Subdirección de Servicios de Salud | F9: Dirección Corporativa de Administración | G9: SEGURIDAD Y SOBREVIVENCIA COSTA AFUERA | H9: Presencial | I9: 245435 | J9: Cesar Valencia Viveros | K9: 24 | L9: 3 | M9: 13 | N9: 44257 | O9: 44259
A10: 2 | B10: 50614487 | D10: Dos Bocas | E10: Subdirección de Servicios de Salud | F10: Dirección Corporativa de Administración | G10: SEGURIDAD Y SOBREVIVENCIA COSTA AFUERA | H10: Presencial | I10: 245435 | J10: Cesar Valencia Viveros | K10: 24 | L10: 3 | M10: 13 | N10: 44271 | O10: 44273
A11: 3 | B11: 50608247 | D11: Dos Bocas | E11: Subdirección de Coordinación Operativa y Comercial | F11: Gerencia de Medición y Balances | G11: SEGURIDAD Y SOBREVIVENCIA COSTA AFUERA | H11: Presencial | I11: 245435 | J11: Cesar Valencia Viveros | K11: 24 | L11: 3 | M11: 8 | N11: 44278 | O11: 44280
A12: 4 | D12: Ciudad del Carmen | E12: Subdirección de Producción Región Marina Noreste | F12: Activo de Producción Ku Maloob Zaap | G12: REACREDITACION DE SIGNATARIOS DEL SPPTR | H12: A distancia | I12: 497025 | J12: Jonathan Olguin Castellanos | K12: 8 | L12: 2 | M12: 13 | N12: 44309 | O12: 44310 | P12: Adicional
A13: 5 | B13: 50615599 | D13: Dos Bocas | E13: Subdirección de Administración de Servicios para Exploración y Producción | F13: Gerencia de Servicios de Soporte y Logística Marina | G13: REACREDITACION DE SIGNATARIOS DEL SPPTR | H13: Presencial | K13: 8 | L13: 1 | M13: 10 | N13: 44329 | O13: 44329
A14: 6 | B14: 50609904 | D14: Dos Bocas | E14: Subdirección de Perforación y Mantenimiento de Pozos | F14: GPRPM | G14: SEGURIDAD Y SOBREVIVENCIA COSTA AFUERA | H14: Presencial | K14: 24 | L14: 3 | M14: 14 | N14: 44329 | O14: 44331
A15: 7 | B15: 50615628 | D15: Dos Bocas | E15: Subdirección de Administración de Servicios para Exploración y Producción | F15: Gerencia de Servicios de Soporte y Logística Marina | G15: REACREDITACION DE SIGNATARIOS DEL SPPTR | H15: Presencial | K15: 8 | L15: 1 | M15: 9 | N15: 44330 | O15: 44330
A16: 8 | B16: 50611089 | C16: Tinajas | D16: Perforación | E16: Subdirección de Perforación y Mantenimiento de Pozos | F16: GPRPN | G16: BASICO DE SEGURIDAD (BS) | H16: Presencial | I16: 318824 | J16: David Antonio Amador Castillo | K16: 16 | L16: 2 | M16: 5 | N16: 06-05-2021 | O16: 44323
A17: 11 | C17: Villahermosa | D17: Sur | E17: Subdirección de Seguridad, Salud en el Trabajo y Protección Ambiental | F17: GSSTPARS | G17: INVESTIGACION DE INCIDENTES Y ANALISIS DE CAUSA RAIZ (IIACR) | H17: A distancia | J17: José del Carmen Contreras Cruz | K17: 9 | L17: 3 | M17: 14 | N17: 44320 | O17: 44323
A18: 12 | B18: 50616715 | D18: Ciudad del Carmen | E18: Subdirección de Administración de Servicios para Exploración y Producción | F18: Coordinación de Servicios Marinos y de Mantenimiento, Confiabilidad y Construcción de Infraestructura | G18: SEGURIDAD EN CENTROS ADMINISTRATIVOS | H18: Presencial | I18: 354951 | J18: Raul Armando Garza Torre | K18: 8 | L18: 1 | M18: 11 | N18: 44361 | O18: 44361 | P18: Adicional PEP-DE-SASEP-CSMMCCI-1162-2021
A19: 13 | B19: 50611116 | D19: Ciudad del Carmen | E19: Subdirección de Administración de Servicios para Exploración y Producción | F19: Coordinación de Servicios Marinos y de Mantenimiento, Confiabilidad y Construcción de Infraestructura | G19: SEGURIDAD EN CENTROS ADMINISTRATIVOS | H19: Presencial | I19: 354951 | J19: Raul Armando Garza Torre | K19: 8 | L19: 1 | M19: 11 | N19: 44362 | O19: 44362 | P19: Adicional PEP-DE-SASEP-CSMMCCI-1162-2021
A20: 14 | B20: 50614584 | D20: Ciudad del Carmen | E20: Subdirección de Producción Región Marina Noreste | F20: Activo de Producción Ku Maloob Zaap | H20: A distancia | I20: 458886 | J20: Edgar Mendoza Rodríguez | K20: 8 | L20: 2 | M20: 14 | N20: 44314 | O20: 44315 | P20: Adicional PEP-DG-SPRMNE-AAPKMZ-607-2021
A21: 15 | B21: 50614583 | D21: Ciudad del Carmen | E21: Subdirección de Producción Región Marina Noreste | F21: Activo de Producción Ku Maloob Zaap | H21: A distancia | I21: 458886 | J21: Edgar Mendoza Rodríguez | K21: 8 | L21: 2 | M21: 13 | N21: 44309 | O21: 44310 | P21: Adicional PEP-DG-SPRMNE-AAPKMZ-468-2021
A22: 16 | B22: 50615668 | D22: Ciudad del Carmen | E22: Subdirección de Administración de Servicios para Exploración y Producción | F22: Gerencia de Servicios de Soporte y Logítica Marina | H22: Presencial | I22: 374253 | J22: Eduardo González Rodríguez | K22: 16 | L22: 2 | M22: 8 | N22: 44357 | O22: 44358 | P22: Adicional PEP-DG-SASEP-GSSLM-324-2021
A23: 17 | B23: 50616719 | D23: Ciudad del Carmen | E23: Subdirección de Administración de Servicios para Exploración y Producción | F23: Coordinación de Servicios Marinos y de Mantenimiento, Confiabilidad y Construcción de Infraestructura | G23: SEGURIDAD EN CENTROS ADMINISTRACIONS (SCA) | H23: Presencial | I23: 354951 | J23: Raul Armando Garza Torre | K23: 8 | L23: 1 | M23: 11 | N23: 44377 | O23: 44377 | P23: Adicional PEP-DE-SASEP-CSMMCCI-1162-2021
A24: 18 | D24: Ciudad del Carmen | E24: Subdirección de Administración de Servicios para Exploración y Producción | F24: Coordinación de Servicios Marinos y de Mantenimiento, Confiabilidad y Construcción de Infraestructura | G24: SEGURIDAD EN CENTROS ADMINISTRACIONS (SCA) | H24: Presencial | I24: 354951 | J24: Raul Armando Garza Torre | K24: 8 | L24: 1 | M24: 10 | N24: 44375 | O24: 44375 | P24: Adicional PEP-DE-SASEP-CSMMCCI-1162-2021
A25: 19 | B25: 50615665 | D25: Ciudad del Carmen | E25: Subdirección de Administración de Servicios para Exploración y Producción | F25: Gerencia de Servicios de Soporte y Logítica Marina | G25: DISCIPLINA OPERATIVA | H25: Presencial | I25: 510745 | J25: César Iván Chulines Granados | K25: 16 | L25: 2 | M25: 3 | N25: 44389 | O25: 44390 | P25: Adicional PEP-DG-SASEP-GSSLM-324-2021
A26: 20 | B26: 50617742 | C26: Agua Dulce | D26: Sur | E26: Subdirección de Producción Región Sur | F26: APCP | G26: Capacitación Integral Normas Oficiales Mexicanas | H26: Presencial | M26: 9 | P26: Capacitación Integral Normas Oficiales Mexicanas
A27: 21 | D27: Ciudad del Carmen | E27: Subdirección de Administración de Servicios para Exploración y Producción | F27: Gerencia de Servicios de Soporte y Logística Marina | G27: BASICO DE SEGURIDAD | H27: Presencial | I27: 458886 | J27: Edgar Mendoza Rodríguez | N27: 44435 | O27: 44436 | P27: Adicional PEP-DG-SASEP-GSSLM-324-2021
