Workbook
Name A: #REF!
Name B: #REF!
Name BAJAS2: #REF!
Name ColumnTitle2: #REF!
Name ColumnTitle3: [1]!Exercise[[#Headers],[DATE]]
Name DietLastEnd: '[1]Chart Calculations'!$C$5
Name DietPeriod: #REF!
Name DietRowStart: '[1]Chart Calculations'!$C$4
Name EndDate: #REF!
Name EndWeight: #REF!
Name ExerciseLastEnd: '[1]Chart Calculations'!$C$23
Name ExercisePeriod: [1]!Exercise[DATE]
Name ExerciseRowStart: '[1]Chart Calculations'!$C$22
Name LossPerDay: [2]TABLERO!#REF!
Name PlanDays: [2]TABLERO!#REF!
Name StartDate: #REF!
Name StartWeight: #REF!
Name WeightGoal: #REF!

Sheet Hoja1
B3: Etiquetas de columna
B4: 1 | C4: 2 | D4: 3 | E4: 4 | F4: 5 | G4: 6 | H4: 7 | I4: 8 | J4: 9 | K4: 10 | L4: 11 | M4: 12 | N4: Total general
A5: Cuenta de Mes | B5: 29 | C5: 87 | D5: 143 | E5: 143 | F5: 206 | G5: 208 | H5: 124 | I5: 104 | J5: 146 | K5: 98 | L5: 85 | M5: 26 | N5: 1399
B11: 1 | C11: 2 | D11: 3 | E11: 4 | F11: 5 | G11: 6 | H11: 7 | I11: 8 | J11: 9 | K11: 10 | L11: 11 | M11: 12 | N11: Total general
A12: Cuenta de Mes | B12: 29 | C12: 87 | D12: 143 | E12: 143 | F12: 206 | G12: 208 | H12: 124 | I12: 104 | J12: 146 | K12: 98 | L12: 85 | M12: 26 | N12: 1399
B14: =B12*100/$N$12 -> 2.0729092 | C14: =C12*100/$N$12 -> 6.2187277 | D14: =D12*100/$N$12 -> 10.221587 | E14: =E12*100/$N$12 -> 10.221587 | F14: =F12*100/$N$12 -> 14.724803 | G14: =G12*100/$N$12 -> 14.867763 | H14: =H12*100/$N$12 -> 8.8634739 | I14: =I12*100/$N$12 -> 7.4338813 | ... N14: =N12*100/$N$12 -> 100
B15: =B14 -> 2.0729092 | C15: =C14+B15 -> 8.2916369 | D15: =D14+C15 -> 18.513224 | E15: =E14+D15 -> 28.734811 | F15: =F14+E15 -> 43.459614 | G15: =G14+F15 -> 58.327377 | H15: =H14+G15 -> 67.190851 | I15: =I14+H15 -> 74.624732 | J15: =J14+I15 -> 85.060758 | ... M15: =M14+L15 -> 100

Sheet PICADE
A1: IDSDNCA | B1: IDSAP | C1: Subdirección | D1: Gerencia/Activo | E1: Nombre Evento Original | F1: Ficha Instructor | G1: Nombre Instructor | H1: Asistentes Programados | I1: Fecha de Inicio | J1: Fecha de Termino | K1: Sede | L1: Mes
A2: 56466 | C2: SPRN | D2: ACTIVO DE PRODUCCIÓN POZA RICA - ALTAMIRA | E2: AUDITORÍAS EFECTIVAS (AE) | F2: 457409 | G2: SAVINO COMSILLE MARIA GUADALUPE | H2: 9 | I2: 45103 | J2: 45103 | K2: ALTAMIRA, TAMAULIPAS | L2: =MONTH(J2) -> 6
A3: 48052 | C3: SPRN | D3: ACTIVO DE PRODUCCIÓN POZA RICA - ALTAMIRA | E3: DISCIPLINA OPERATIVA (DO) | F3: 449433 | G3: MORAL JORDAN GONZALO | H3: 15 | I3: 45168 | J3: 45169 | K3: ALTAMIRA, TAMAULIPAS | L3: =MONTH(J3) -> 8
A4: 53782 | C4: SPRN | D4: ACTIVO DE PRODUCCIÓN POZA RICA - ALTAMIRA | E4: BRIGADAS DE BÚSQUEDA Y RESCATE (BBR) | F4: 449433 | G4: MORAL JORDAN GONZALO | H4: 18 | I4: 45243 | J4: 45245 | K4: ALTAMIRA, TAMAULIPAS | L4: =MONTH(J4) -> 11
A5: 51027 | C5: SPRN | D5: ACTIVO DE PRODUCCIÓN POZA RICA - ALTAMIRA | E5: BÁSICO DE SEGURIDAD (BS) | F5: 457409 | G5: SAVINO COMSILLE MARIA GUADALUPE | H5: 9 | I5: 45173 | J5: 45174 | K5: ALTAMIRA, TAMAULIPAS | L5: =MONTH(J5) -> 9
A6: 55346 | C6: SPRN | D6: ACTIVO DE PRODUCCIÓN POZA RICA - ALTAMIRA | E6: SEGURIDAD EN CENTROS ADMINISTRATIVOS (SCA) | F6: 196853 | G6: DEL ANGEL DEL ANGEL JUSTO JESUS | H6: 18 | I6: 44966 | J6: 44966 | K6: NARANJOS | L6: =MONTH(J6) -> 2
A7: 50466 | C7: SPRN | D7: ACTIVO DE PRODUCCIÓN POZA RICA - ALTAMIRA | E7: ÁCIDO SULFHÍDRICO (H2S) | F7: 449433 | G7: MORAL JORDAN GONZALO | H7: 14 | I7: 45054 | J7: 45054 | K7: ALTAMIRA, TAMAULIPAS | L7: =MONTH(J7) -> 5
A8: 53740 | C8: SPRN | D8: ACTIVO DE PRODUCCIÓN POZA RICA - ALTAMIRA | E8: BRIGADAS DE PRIMEROS AUXILIOS (BPA) | F8: 449433 | G8: MORAL JORDAN GONZALO | H8: 14 | I8: 45225 | J8: 45226 | K8: ALTAMIRA, TAMAULIPAS | L8: =MONTH(J8) -> 10
A9: 58434 | C9: SPRN | D9: ACTIVO DE PRODUCCIÓN POZA RICA - ALTAMIRA | E9: AUDITORÍAS EFECTIVAS (AE) | F9: 457409 | G9: SAVINO COMSILLE MARIA GUADALUPE | H9: 14 | I9: 45170 | J9: 45170 | K9: POZA RICA DE HIDALGO,VERACRUZ | L9: =MONTH(J9) -> 9
A10: 47731 | C10: SPRN | D10: ACTIVO DE PRODUCCIÓN POZA RICA - ALTAMIRA | E10: ÁCIDO SULFHÍDRICO (H2S) | F10: 449433 | G10: MORAL JORDAN GONZALO | H10: 12 | I10: 45079 | J10: 45079 | K10: ALTAMIRA, TAMAULIPAS | L10: =MONTH(J10) -> 6
A11: 47721 | C11: SPRN | D11: ACTIVO DE PRODUCCIÓN POZA RICA - ALTAMIRA | E11: MANEJO A LA DEFENSIVA (MD) | F11: 315766 | G11: RANGEL RIVAS ROCIO | H11: 13 | I11: 45071 | J11: 45071 | K11: ALTAMIRA, TAMAULIPAS | L11: =MONTH(J11) -> 5
A12: 59718 | C12: SPRN | D12: ACTIVO DE PRODUCCIÓN POZA RICA - ALTAMIRA | E12: AUDITORÍAS EFECTIVAS (AE) | F12: 457409 | G12: SAVINO COMSILLE MARIA GUADALUPE | H12: 10 | I12: 45233 | J12: 45233 | K12: POZA RICA DE HIDALGO,VERACRUZ | L12: =MONTH(J12) -> 11
A13: 55768 | C13: SPRN | D13: ACTIVO DE PRODUCCIÓN POZA RICA - ALTAMIRA | E13: SEGURIDAD EN CENTROS ADMINISTRATIVOS (SCA) | F13: 372624 | G13: CARRILLO CABELLO JAIR DE JESUS | H13: 18 | I13: 45064 | J13: 45064 | K13: CERRO AZUL,VERACRUZ | L13: =MONTH(J13) -> 5
... A1400: 47975 | C1400: SMLIC | D1400: GERENCIA DE SERVICIOS DE LOGÍSTICA TERRESTRE | E1400: MANEJO A LA DEFENSIVA (MD) | F1400: 372624 | G1400: CARRILLO CABELLO JAIR DE JESUS | H1400: 10 | I1400: 45019 | J1400: 45019 | K1400: NARANJOS | L1400: =MONTH(J1400) -> 4

Sheet Seguimiento
A1: Rsspa
E5: Periodo
C6: PICADE Autorizado | E6: 44927 | I6: al | J6: 45291
B7: PEP | C7: Cursos | D7: Capacitandos | E7: Programados en el periodo | F7: Realizados en el periodo | G7: Cancelados | H7: Adicionales | I7: Total Realizados | J7: Capacitandos programados | K7: Capacitados en el periodo | L7: Capacitados Adicionales | M7: Total Capacitandos | N7: Cumplimiento en el periodo (%) | O7: Avance del PICADE (%) | P7: Cumplimiento del personal capacitado (%) | Q7: Trabajadores por curso
B8: Norte | C8: =C26 -> 387 | D8: =D26 -> 4659 | E8: =E26 -> 387 | F8: =F26 -> 381 | G8: =G26 -> 6 | H8: =H26 -> 3 | I8: =I26 -> 384 | J8: =J26 -> 4659 | ... M8: =M26 -> 4085 | N8: =IFERROR(F8/E8, "-") -> 0.98449612 | O8: =IFERROR(F8/C8, "-") -> 0.98449612 | P8: =IFERROR(M8/D8, "-") -> 0.8767976 | Q8: =IFERROR(M8/I8,"-") -> 10.638021
B9: Sur | C9: =C34 -> 327 | D9: =D34 -> 4751 | E9: =E34 -> 327 | F9: =F34 -> 286 | G9: =G34 -> 41 | H9: =H34 -> 39 | I9: =I34 -> 325 | J9: =J34 -> 4751 | ... M9: =M34 -> 3729 | N9: =IFERROR(F9/E9, "-") -> 0.87461774 | O9: =IFERROR(F9/C9, "-") -> 0.87461774 | P9: =IFERROR(M9/D9, "-") -> 0.78488739 | Q9: =IFERROR(M9/I9,"-") -> 11.473846
B10: CASES Carmen Producción | C10: =C41 -> 147 | D10: =D41 -> 1667 | E10: =E41 -> 147 | F10: =F41 -> 138 | G10: =G41 -> 9 | H10: =H41 -> 12 | I10: =I41 -> 150 | J10: =J41 -> 1667 | ... M10: =M41 -> 1488 | N10: =IFERROR(F10/E10, "-") -> 0.93877551 | O10: =IFERROR(F10/C10, "-") -> 0.93877551 | P10: =IFERROR(M10/D10, "-") -> 0.89262148 | Q10: =IFERROR(M10/I10,"-") -> 9.92
B11: CASES Carmen Perforación | C11: =C37 -> 152 | D11: =D37 -> 2037 | E11: =E37 -> 152 | F11: =F37 -> 151 | G11: =G37 -> 1 | H11: =H37 -> 0 | I11: =I37 -> 151 | J11: =J37 -> 0 | ... M11: =M37 -> 1479 | N11: =IFERROR(F11/E11, "-") -> 0.99342105 | O11: =IFERROR(F11/C11, "-") -> 0.99342105 | P11: =IFERROR(M11/D11, "-") -> 0.72606775 | Q11: =IFERROR(M11/I11,"-") -> 9.794702
B12: CASES DB Producción | C12: =C42 -> 220 | D12: =D42 -> 3153 | E12: =E42 -> 220 | F12: =F42 -> 216 | G12: =G42 -> 4 | H12: =H42 -> 12 | I12: =I42 -> 228 | J12: =J42 -> 3153 | ... M12: =M42 -> 2648 | N12: =IFERROR(F12/E12, "-") -> 0.98181818 | O12: =IFERROR(F12/C12, "-") -> 0.98181818 | P12: =IFERROR(M12/D12, "-") -> 0.83983508 | Q12: =IFERROR(M12/I12,"-") -> 11.614035
B13: CASES DB Perforación | C13: =C38 -> 8 | D13: =D38 -> 62 | E13: =E38 -> 8 | F13: =F38 -> 8 | G13: =G38 -> 0 | H13: =H38 -> 2 | I13: =I38 -> 10 | J13: =J38 -> 0 | ... M13: =M38 -> 59 | N13: =IFERROR(F13/E13, "-") -> 1 | O13: =IFERROR(F13/C13, "-") -> 1 | P13: =IFERROR(M13/D13, "-") -> 0.9516129 | Q13: =IFERROR(M13/I13,"-") -> 5.9
B14: Perforación Terrestre | C14: =C36 -> 158 | D14: =D36 -> 1485 | E14: =E36 -> 158 | F14: =F36 -> 148 | G14: =G36 -> 10 | H14: =H36 -> 5 | I14: =I36 -> 153 | J14: =J36 -> 1485 | ... M14: =M36 -> 1062 | N14: =IFERROR(F14/E14, "-") -> 0.93670886 | O14: =IFERROR(F14/C14, "-") -> 0.93670886 | P14: =IFERROR(M14/D14, "-") -> 0.71515152 | Q14: =IFERROR(M14/I14,"-") -> 6.9411765
B15: Total PEP | C15: =SUM(C26,C34,C39,C43) -> 1399 | D15: =SUM(D26,D34,D39,D43) -> 17814 | E15: =SUM(E26,E34,E39,E43) -> 1399 | F15: =SUM(F26,F34,F39,F43) -> 1328 | G15: =SUM(G26,G34,G39,G43) -> 71 | H15: =SUM(H26,H34,H39,H43) -> 73 | I15: =SUM(I26,I34,I39,I43) -> 1401 | J15: =SUM(J26,J34,J39,J43) -> 15715 | ... M15: =SUM(M26,M34,M39,M43) -> 14550 | N15: =IFERROR(F15/E15, "-") -> 0.94924946 | O15: =IFERROR(F15/C15, "-") -> 0.94924946 | P15: =IFERROR(M15/D15, "-") -> 0.81677332 | Q15: =IFERROR(M15/I15,"-") -> 10.385439
E16: =IF((SUM(F15:G15)<E15),"Faltan ","Correcto") -> Correcto | F16: =IF(E15-SUM(F15:G15)=0,0,E15-SUM(F15:G15)) -> 0 | G16: registros | N16: =1-N15 -> 0.050750536 | O16: =1-O15 -> 0.050750536
B19: Reynosa | C19: =Reynosa!$H$5 -> 66 | D19: =Reynosa!$I$5 -> 869 | E19: =Reynosa!$J$5 -> 66 | F19: =Reynosa!$K$5 -> 66 | G19: =Reynosa!$L$5 -> 0 | H19: =Adicionales!F2 -> 0 | I19: =SUM(F19,H19) -> 66 | J19: =Reynosa!$N$5 -> 869 | K19: =Reynosa!$O$5 -> 825 | L19: =Adicionales!G2 -> 0 | M19: =SUM(K19:L19) -> 825 | N19: =IFERROR(F19/E19, "-") -> 1 | O19: =IFERROR(F19/C19, "-") -> 1
B20: Altamira | C20: =Altamira!$H$5 -> 55 | D20: =Altamira!$I$5 -> 635 | E20: =Altamira!$J$5 -> 55 | F20: =Altamira!$K$5 -> 55 | G20: =Altamira!$L$5 -> 0 | H20: =Adicionales!F3 -> 0 | I20: =SUM(F20,H20) -> 55 | J20: =Altamira!$N$5 -> 635 | K20: =Altamira!$O$5 -> 546 | L20: =Adicionales!G3 -> 0 | M20: =SUM(K20:L20) -> 546 | N20: =IFERROR(F20/E20, "-") -> 1 | O20: =IFERROR(F20/C20, "-") -> 1
B21: Naranjos | C21: =Naranjos!$H$5 -> 21 | D21: =Naranjos!$I$5 -> 328 | E21: =Naranjos!$J$5 -> 21 | F21: =Naranjos!$K$5 -> 21 | G21: =Naranjos!$L$5 -> 0 | H21: =Adicionales!F4 -> 0 | I21: =SUM(F21,H21) -> 21 | J21: =Naranjos!$N$5 -> 328 | K21: =Naranjos!$O$5 -> 300 | L21: =Adicionales!G4 -> 0 | M21: =SUM(K21:L21) -> 300 | N21: =IFERROR(F21/E21, "-") -> 1 | O21: =IFERROR(F21/C21, "-") -> 1
B22: Cerro Azul | C22: =Cerro_Azul!H5 -> 33 | D22: =Cerro_Azul!I5 -> 440 | E22: =Cerro_Azul!J5 -> 33 | F22: =Cerro_Azul!K5 -> 33 | G22: =Cerro_Azul!L5 -> 0 | H22: =Adicionales!F5 -> 0 | I22: =SUM(F22,H22) -> 33 | J22: =Cerro_Azul!N5 -> 440 | K22: =Cerro_Azul!O5 -> 360 | L22: =Adicionales!G5 -> 0 | M22: =SUM(K22:L22) -> 360 | N22: =IFERROR(F22/E22, "-") -> 1 | O22: =IFERROR(F22/C22, "-") -> 1
B23: Poza Rica | C23: =Poza_Rica!$H$5 -> 79 | D23: =Poza_Rica!$I$5 -> 1024 | E23: =Poza_Rica!$J$5 -> 79 | F23: =Poza_Rica!$K$5 -> 75 | G23: =Poza_Rica!$L$5 -> 4 | H23: =Adicionales!F6 -> 3 | I23: =SUM(F23,H23) -> 78 | J23: =Poza_Rica!$N$5 -> 1024 | K23: =Poza_Rica!$O$5 -> 799 | L23: =Adicionales!G6 -> 50 | M23: =SUM(K23:L23) -> 849 | N23: =IFERROR(F23/E23, "-") -> 0.94936709 | O23: =IFERROR(F23/C23, "-") -> 0.94936709
B24: Veracruz | C24: =Veracruz!$H$5 -> 128 | D24: =Veracruz!$I$5 -> 1329 | E24: =Veracruz!$J$5 -> 128 | F24: =Veracruz!$K$5 -> 126 | G24: =Veracruz!$L$5 -> 2 | H24: =Adicionales!F7 -> 0 | I24: =SUM(F24,H24) -> 126 | J24: =Veracruz!$N$5 -> 1329 | K24: =Veracruz!$O$5 -> 1166 | L24: =Adicionales!G7 -> 0 | M24: =SUM(K24:L24) -> 1166 | N24: =IFERROR(F24/E24, "-") -> 0.984375 | O24: =IFERROR(F24/C24, "-") -> 0.984375
B25: Cd. Madero | C25: =Cd_Madero!$H$5 -> 5 | D25: =Cd_Madero!$I$5 -> 34 | E25: =Cd_Madero!$J$5 -> 5 | F25: =Cd_Madero!$K$5 -> 5 | G25: =Cd_Madero!$L$5 -> 0 | H25: =Adicionales!F8 -> 0 | I25: =SUM(F25,H25) -> 5 | J25: =Cd_Madero!$N$5 -> 34 | K25: =Cd_Madero!$O$5 -> 39 | L25: =Adicionales!G8 -> 0 | M25: =SUM(K25:L25) -> 39 | N25: =IFERROR(F25/E25, "-") -> 1 | O25: =IFERROR(F25/C25, "-") -> 1
B26: Región Norte | C26: =SUM(C19:C25) -> 387 | D26: =SUM(D19:D25) -> 4659 | E26: =SUM(E19:E25) -> 387 | F26: =SUM(F19:F25) -> 381 | G26: =SUM(G19:G25) -> 6 | H26: =SUM(H19:H25) -> 3 | I26: =SUM(I19:I25) -> 384 | J26: =SUM(J19:J25) -> 4659 | ... M26: =SUM(M19:M25) -> 4085 | N26: =IFERROR(F26/E26, "-") -> 0.98449612 | O26: =IFERROR(F26/C26, "-") -> 0.98449612
B28: Agua Dulce | C28: =Agua_Dulce!$H$5 -> 85 | D28: =Agua_Dulce!$I$5 -> 1407 | E28: =Agua_Dulce!$J$5 -> 85 | F28: =Agua_Dulce!$K$5 -> 71 | G28: =Agua_Dulce!$L$5 -> 14 | H28: =Adicionales!F9 -> 12 | I28: =SUM(F28,H28) -> 83 | J28: =Agua_Dulce!$N$5 -> 1407 | K28: =Agua_Dulce!$O$5 -> 782 | L28: =Adicionales!G9 -> 201 | M28: =SUM(K28:L28) -> 983 | N28: =IFERROR(F28/E28, "-") -> 0.83529412 | O28: =IFERROR(F28/C28, "-") -> 0.83529412
B29: Comalcalco | C29: =Comalcalco!$H$5 -> 31 | D29: =Comalcalco!$I$5 -> 456 | E29: =Comalcalco!$J$5 -> 31 | F29: =Comalcalco!$K$5 -> 31 | G29: =Comalcalco!$L$5 -> 0 | H29: =Adicionales!F10 -> 8 | I29: =SUM(F29,H29) -> 39 | J29: =Comalcalco!$N$5 -> 456 | K29: =Comalcalco!$O$5 -> 372 | L29: =Adicionales!G10 -> 33 | M29: =SUM(K29:L29) -> 405 | N29: =IFERROR(F29/E29, "-") -> 1 | O29: =IFERROR(F29/C29, "-") -> 1
B30: El Castaño | C30: =El_Castaño!$H$5 -> 35 | D30: =El_Castaño!$I$5 -> 488 | E30: =El_Castaño!$J$5 -> 35 | F30: =El_Castaño!$K$5 -> 33 | G30: =El_Castaño!$L$5 -> 2 | H30: =Adicionales!F11 -> 2 | I30: =SUM(F30,H30) -> 35 | J30: =El_Castaño!$N$5 -> 488 | K30: =El_Castaño!$O$5 -> 370 | L30: =Adicionales!G11 -> 7 | M30: =SUM(K30:L30) -> 377 | N30: =IFERROR(F30/E30, "-") -> 0.94285714 | O30: =IFERROR(F30/C30, "-") -> 0.94285714
B31: Reforma | C31: =Reforma!$H$5 -> 79 | D31: =Reforma!$I$5 -> 916 | E31: =Reforma!$J$5 -> 79 | F31: =Reforma!$K$5 -> 65 | G31: =Reforma!$L$5 -> 14 | H31: =Adicionales!F12 -> 2 | I31: =SUM(F31,H31) -> 67 | J31: =Reforma!$N$5 -> 916 | K31: =Reforma!$O$5 -> 600 | L31: =Adicionales!G12 -> 25 | M31: =SUM(K31:L31) -> 625 | N31: =IFERROR(F31/E31, "-") -> 0.82278481 | O31: =IFERROR(F31/C31, "-") -> 0.82278481
B32: Cunduacán | C32: =Cunduacán!$H$5 -> 63 | D32: =Cunduacán!$I$5 -> 1000 | E32: =Cunduacán!$J$5 -> 63 | F32: =Cunduacán!$K$5 -> 62 | G32: =Cunduacán!$L$5 -> 1 | H32: =Adicionales!F13 -> 3 | I32: =SUM(F32,H32) -> 65 | J32: =Cunduacán!$N$5 -> 1000 | K32: =Cunduacán!$O$5 -> 807 | L32: =Adicionales!G13 -> 30 | M32: =SUM(K32:L32) -> 837 | N32: =IFERROR(F32/E32, "-") -> 0.98412698 | O32: =IFERROR(F32/C32, "-") -> 0.98412698
B33: Villahermosa | C33: =Villahermosa!$H$5 -> 34 | D33: =Villahermosa!$I$5 -> 484 | E33: =Villahermosa!$J$5 -> 34 | F33: =Villahermosa!$K$5 -> 24 | G33: =Villahermosa!$L$5 -> 10 | H33: =Adicionales!F14 -> 12 | I33: =SUM(F33,H33) -> 36 | J33: =Villahermosa!$N$5 -> 484 | K33: =Villahermosa!$O$5 -> 277 | L33: =Adicionales!G14 -> 225 | M33: =SUM(K33:L33) -> 502 | N33: =IFERROR(F33/E33, "-") -> 0.70588235 | O33: =IFERROR(F33/C33, "-") -> 0.70588235
B34: Región Sur | C34: =SUM(C28:C33) -> 327 | D34: =SUM(D28:D33) -> 4751 | E34: =SUM(E28:E33) -> 327 | F34: =SUM(F28:F33) -> 286 | G34: =SUM(G28:G33) -> 41 | H34: =SUM(H28:H33) -> 39 | I34: =SUM(I28:I33) -> 325 | J34: =SUM(J28:J33) -> 4751 | ... M34: =SUM(M28:M33) -> 3729 | N34: =IFERROR(I34/E34, "-") -> 0.99388379 | O34: =IFERROR(F34/C34, "-") -> 0.87461774
B36: SPMP_Tierra | C36: =SPMP_Tierra!H5 -> 158 | D36: =SPMP_Tierra!I5 -> 1485 | E36: =SPMP_Tierra!J5 -> 158 | F36: =SPMP_Tierra!K5 -> 148 | G36: =SPMP_Tierra!L5 -> 10 | H36: =Adicionales!$F$15 -> 5 | I36: =SUM(F36,H36) -> 153 | J36: =SPMP_Tierra!N5 -> 1485 | K36: =SPMP_Tierra!O5 -> 1031 | L36: =Adicionales!$G$15 -> 31 | M36: =SUM(K36:L36) -> 1062 | N36: =IFERROR(F36/E36, "-") -> 0.93670886 | O36: =IFERROR(F36/C36, "-") -> 0.93670886
B37: SPMP_Mar Carmen | C37: =SPMP_Mar!H6 -> 152 | D37: =SPMP_Mar!I6 -> 2037 | E37: =SPMP_Mar!J6 -> 152 | F37: =SPMP_Mar!K6 -> 151 | G37: =SPMP_Mar!L6 -> 1 | H37: =Adicionales!F16 -> 0 | I37: =SUM(F37,H37) -> 151 | J37: =SPMP_Mar!N6 -> 0 | K37: =SPMP_Mar!O6 -> 0 | L37: =SPMP_Mar!P6 -> 2037 | M37: =SPMP_Mar!Q6 -> 1479 | N37: =IFERROR(F37/E37, "-") -> 0.99342105 | O37: =IFERROR(F37/C37, "-") -> 0.99342105
B38: SPMP_Mar DB | C38: =SPMP_Mar!H5 -> 8 | D38: =SPMP_Mar!I5 -> 62 | E38: =SPMP_Mar!J5 -> 8 | F38: =SPMP_Mar!K5 -> 8 | G38: =SPMP_Mar!L5 -> 0 | H38: =Adicionales!F17 -> 2 | I38: =SUM(F38,H38) -> 10 | J38: =SPMP_Mar!N5 -> 0 | K38: =SPMP_Mar!O5 -> 0 | L38: =SPMP_Mar!P5 -> 62 | M38: =SPMP_Mar!Q5 -> 59 | N38: =IFERROR(F38/E38,"-") -> 1 | O38: =IFERROR(F38/C38, "-") -> 1
B39: Perforación | C39: =SUM(C36:C38) -> 318 | D39: =SUM(D36:D38) -> 3584 | E39: =SUM(E36:E38) -> 318 | F39: =SUM(F36:F38) -> 307 | G39: =SUM(G36:G38) -> 11 | H39: =SUM(H36:H38) -> 7 | I39: =SUM(I36:I38) -> 314 | J39: =SUM(J36:J38) -> 1485 | ... M39: =SUM(M36:M38) -> 2600 | N39: =IFERROR(F39/E39, "-") -> 0.96540881 | O39: =IFERROR(F39/C39, "-") -> 0.96540881
B41: CASES Carmen | C41: =CASES_Carmen!H5 -> 147 | D41: =CASES_Carmen!I5 -> 1667 | E41: =CASES_Carmen!J5 -> 147 | F41: =CASES_Carmen!K5 -> 138 | G41: =CASES_Carmen!L5 -> 9 | H41: =Adicionales!F18 -> 12 | I41: =SUM(F41,H41) -> 150 | J41: =CASES_Carmen!N5 -> 1667 | K41: =CASES_Carmen!O5 -> 1358 | L41: =Adicionales!G18 -> 130 | M41: =SUM(K41:L41) -> 1488 | N41: =IFERROR(F41/E41, "-") -> 0.93877551 | O41: =IFERROR(F41/C41, "-") -> 0.93877551
B42: CASES DB | C42: =CASES_DB!H5 -> 220 | D42: =CASES_DB!I5 -> 3153 | E42: =CASES_DB!J5 -> 220 | F42: =CASES_DB!K5 -> 216 | G42: =CASES_DB!L5 -> 4 | H42: =Adicionales!F19 -> 12 | I42: =SUM(F42,H42) -> 228 | J42: =CASES_DB!N5 -> 3153 | K42: =CASES_DB!O5 -> 2418 | L42: =Adicionales!G19 -> 230 | M42: =SUM(K42:L42) -> 2648 | N42: =IFERROR(F42/E42, "-") -> 0.98181818 | O42: =IFERROR(F42/C42, "-") -> 0.98181818
B43: Región Marina | C43: =SUM(C41:C42) -> 367 | D43: =SUM(D41:D42) -> 4820 | E43: =SUM(E41:E42) -> 367 | F43: =SUM(F41:F42) -> 354 | G43: =SUM(G41:G42) -> 13 | H43: =SUM(H41:H42) -> 24 | I43: =SUM(I41:I42) -> 378 | J43: =SUM(J41:J42) -> 4820 | ... M43: =SUM(M41:M42) -> 4136 | N43: =IFERROR(F43/E43, "-") -> 0.96457766 | O43: =IFERROR(F43/C43, "-") -> 0.96457766

Sheet Adicionales
F1: Cursos | G1: Capacitandos | R1: Adicionales | S1: 1 | T1: 2 | U1: 3 | V1: 4 | W1: 5 | X1: 6 | Y1: 7 | Z1: 8 | AA1: 9 | AB1: 10 | AC1: 11 | AD1: 12 | AE1: Total
E2: Reynosa | F2: =COUNTIFS($N$26:$N$290,1,$C$26:$C$290,$E2) -> 0 | G2: =SUMIFS($K$26:$K$290,$N$26:$N$290,1,$C$26:$C$290,$E2) -> 0 | R2: SCOC | S2: =COUNTIFS($P$26:$P$308,S$1,$D$26:$D$308,$R2) -> 0 | T2: =COUNTIFS($P$26:$P$308,T$1,$D$26:$D$308,$R2) -> 0 | U2: =COUNTIFS($P$26:$P$308,U$1,$D$26:$D$308,$R2) -> 0 | V2: =COUNTIFS($P$26:$P$308,V$1,$D$26:$D$308,$R2) -> 0 | W2: =COUNTIFS($P$26:$P$308,W$1,$D$26:$D$308,$R2) -> 3 | X2: =COUNTIFS($P$26:$P$308,X$1,$D$26:$D$308,$R2) -> 6 | Y2: =COUNTIFS($P$26:$P$308,Y$1,$D$26:$D$308,$R2) -> 0 | Z2: =COUNTIFS($P$26:$P$308,Z$1,$D$26:$D$308,$R2) -> 0 | ... AD2: =COUNTIFS($P$26:$P$308,AD$1,$D$26:$D$308,$R2) -> 0 | AE2: =SUM(S2:AD2) -> 9
B3: =Seguimiento!$E$6 -> 44927 | C3: =Seguimiento!$J$6 -> 45291 | E3: Altamira | F3: =COUNTIFS($N$26:$N$290,1,$C$26:$C$290,$E3) -> 0 | G3: =SUMIFS($K$26:$K$290,$N$26:$N$290,1,$C$26:$C$290,$E3) -> 0 | R3: SE | S3: =COUNTIFS($P$26:$P$308,S$1,$D$26:$D$308,$R3) -> 0 | T3: =COUNTIFS($P$26:$P$308,T$1,$D$26:$D$308,$R3) -> 0 | U3: =COUNTIFS($P$26:$P$308,U$1,$D$26:$D$308,$R3) -> 0 | V3: =COUNTIFS($P$26:$P$308,V$1,$D$26:$D$308,$R3) -> 0 | W3: =COUNTIFS($P$26:$P$308,W$1,$D$26:$D$308,$R3) -> 0 | X3: =COUNTIFS($P$26:$P$308,X$1,$D$26:$D$308,$R3) -> 0 | Y3: =COUNTIFS($P$26:$P$308,Y$1,$D$26:$D$308,$R3) -> 0 | Z3: =COUNTIFS($P$26:$P$308,Z$1,$D$26:$D$308,$R3) -> 0 | ... AD3: =COUNTIFS($P$26:$P$308,AD$1,$D$26:$D$308,$R3) -> 0 | AE3: =SUM(S3:AD3) -> 0
E4: Naranjos | F4: =COUNTIFS($N$26:$N$290,1,$C$26:$C$290,$E4) -> 0 | G4: =SUMIFS($K$26:$K$290,$N$26:$N$290,1,$C$26:$C$290,$E4) -> 0 | R4: SEPCA | S4: =COUNTIFS($P$26:$P$308,S$1,$D$26:$D$308,$R4) -> 0 | T4: =COUNTIFS($P$26:$P$308,T$1,$D$26:$D$308,$R4) -> 0 | U4: =COUNTIFS($P$26:$P$308,U$1,$D$26:$D$308,$R4) -> 0 | V4: =COUNTIFS($P$26:$P$308,V$1,$D$26:$D$308,$R4) -> 0 | W4: =COUNTIFS($P$26:$P$308,W$1,$D$26:$D$308,$R4) -> 0 | X4: =COUNTIFS($P$26:$P$308,X$1,$D$26:$D$308,$R4) -> 0 | Y4: =COUNTIFS($P$26:$P$308,Y$1,$D$26:$D$308,$R4) -> 0 | Z4: =COUNTIFS($P$26:$P$308,Z$1,$D$26:$D$308,$R4) -> 0 | ... AD4: =COUNTIFS($P$26:$P$308,AD$1,$D$26:$D$308,$R4) -> 0 | AE4: =SUM(S4:AD4) -> 0
E5: Cerro Azul | F5: =COUNTIFS($N$26:$N$290,1,$C$26:$C$290,$E5) -> 0 | G5: =SUMIFS($K$26:$K$290,$N$26:$N$290,1,$C$26:$C$290,$E5) -> 0 | R5: SMLIC | S5: =COUNTIFS($P$26:$P$308,S$1,$D$26:$D$308,$R5) -> 0 | T5: =COUNTIFS($P$26:$P$308,T$1,$D$26:$D$308,$R5) -> 0 | U5: =COUNTIFS($P$26:$P$308,U$1,$D$26:$D$308,$R5) -> 0 | V5: =COUNTIFS($P$26:$P$308,V$1,$D$26:$D$308,$R5) -> 0 | W5: =COUNTIFS($P$26:$P$308,W$1,$D$26:$D$308,$R5) -> 0 | X5: =COUNTIFS($P$26:$P$308,X$1,$D$26:$D$308,$R5) -> 0 | Y5: =COUNTIFS($P$26:$P$308,Y$1,$D$26:$D$308,$R5) -> 0 | Z5: =COUNTIFS($P$26:$P$308,Z$1,$D$26:$D$308,$R5) -> 0 | ... AD5: =COUNTIFS($P$26:$P$308,AD$1,$D$26:$D$308,$R5) -> 0 | AE5: =SUM(S5:AD5) -> 0
E6: Poza Rica | F6: =COUNTIFS($N$26:$N$290,1,$C$26:$C$290,$E6) -> 3 | G6: =SUMIFS($K$26:$K$290,$N$26:$N$290,1,$C$26:$C$290,$E6) -> 50 | R6: SPEE | S6: =COUNTIFS($P$26:$P$308,S$1,$D$26:$D$308,$R6) -> 0 | T6: =COUNTIFS($P$26:$P$308,T$1,$D$26:$D$308,$R6) -> 0 | U6: =COUNTIFS($P$26:$P$308,U$1,$D$26:$D$308,$R6) -> 0 | V6: =COUNTIFS($P$26:$P$308,V$1,$D$26:$D$308,$R6) -> 0 | W6: =COUNTIFS($P$26:$P$308,W$1,$D$26:$D$308,$R6) -> 0 | X6: =COUNTIFS($P$26:$P$308,X$1,$D$26:$D$308,$R6) -> 0 | Y6: =COUNTIFS($P$26:$P$308,Y$1,$D$26:$D$308,$R6) -> 0 | Z6: =COUNTIFS($P$26:$P$308,Z$1,$D$26:$D$308,$R6) -> 0 | ... AD6: =COUNTIFS($P$26:$P$308,AD$1,$D$26:$D$308,$R6) -> 0 | AE6: =SUM(S6:AD6) -> 0
E7: Veracruz | F7: =COUNTIFS($N$26:$N$290,1,$C$26:$C$290,$E7) -> 0 | G7: =SUMIFS($K$26:$K$290,$N$26:$N$290,1,$C$26:$C$290,$E7) -> 0 | R7: SPMP | S7: =COUNTIFS($P$26:$P$308,S$1,$D$26:$D$308,$R7) -> 0 | T7: =COUNTIFS($P$26:$P$308,T$1,$D$26:$D$308,$R7) -> 0 | U7: =COUNTIFS($P$26:$P$308,U$1,$D$26:$D$308,$R7) -> 0 | V7: =COUNTIFS($P$26:$P$308,V$1,$D$26:$D$308,$R7) -> 0 | W7: =COUNTIFS($P$26:$P$308,W$1,$D$26:$D$308,$R7) -> 7 | X7: =COUNTIFS($P$26:$P$308,X$1,$D$26:$D$308,$R7) -> 2 | Y7: =COUNTIFS($P$26:$P$308,Y$1,$D$26:$D$308,$R7) -> 0 | Z7: =COUNTIFS($P$26:$P$308,Z$1,$D$26:$D$308,$R7) -> 0 | ... AD7: =COUNTIFS($P$26:$P$308,AD$1,$D$26:$D$308,$R7) -> 0 | AE7: =SUM(S7:AD7) -> 9
E8: Cd. Madero | F8: =COUNTIFS($N$26:$N$290,1,$C$26:$C$290,$E8) -> 0 | G8: =SUMIFS($K$26:$K$290,$N$26:$N$290,1,$C$26:$C$290,$E8) -> 0 | R8: SPRMNE | S8: =COUNTIFS($P$26:$P$308,S$1,$D$26:$D$308,$R8) -> 0 | T8: =COUNTIFS($P$26:$P$308,T$1,$D$26:$D$308,$R8) -> 0 | U8: =COUNTIFS($P$26:$P$308,U$1,$D$26:$D$308,$R8) -> 0 | V8: =COUNTIFS($P$26:$P$308,V$1,$D$26:$D$308,$R8) -> 0 | W8: =COUNTIFS($P$26:$P$308,W$1,$D$26:$D$308,$R8) -> 0 | X8: =COUNTIFS($P$26:$P$308,X$1,$D$26:$D$308,$R8) -> 0 | Y8: =COUNTIFS($P$26:$P$308,Y$1,$D$26:$D$308,$R8) -> 0 | Z8: =COUNTIFS($P$26:$P$308,Z$1,$D$26:$D$308,$R8) -> 0 | ... AD8: =COUNTIFS($P$26:$P$308,AD$1,$D$26:$D$308,$R8) -> 1 | AE8: =SUM(S8:AD8) -> 1
E9: Agua Dulce | F9: =COUNTIFS($N$26:$N$290,1,$C$26:$C$290,$E9) -> 12 | G9: =SUMIFS($K$26:$K$290,$N$26:$N$290,1,$C$26:$C$290,$E9) -> 201 | R9: SPRMSO | S9: =COUNTIFS($P$26:$P$308,S$1,$D$26:$D$308,$R9) -> 0 | T9: =COUNTIFS($P$26:$P$308,T$1,$D$26:$D$308,$R9) -> 0 | U9: =COUNTIFS($P$26:$P$308,U$1,$D$26:$D$308,$R9) -> 0 | V9: =COUNTIFS($P$26:$P$308,V$1,$D$26:$D$308,$R9) -> 0 | W9: =COUNTIFS($P$26:$P$308,W$1,$D$26:$D$308,$R9) -> 0 | X9: =COUNTIFS($P$26:$P$308,X$1,$D$26:$D$308,$R9) -> 0 | Y9: =COUNTIFS($P$26:$P$308,Y$1,$D$26:$D$308,$R9) -> 0 | Z9: =COUNTIFS($P$26:$P$308,Z$1,$D$26:$D$308,$R9) -> 0 | ... AD9: =COUNTIFS($P$26:$P$308,AD$1,$D$26:$D$308,$R9) -> 0 | AE9: =SUM(S9:AD9) -> 0
E10: Comalcalco | F10: =COUNTIFS($N$26:$N$290,1,$C$26:$C$290,$E10) -> 8 | G10: =SUMIFS($K$26:$K$290,$N$26:$N$290,1,$C$26:$C$290,$E10) -> 33 | R10: SPRN | S10: =COUNTIFS($P$26:$P$308,S$1,$D$26:$D$308,$R10) -> 0 | T10: =COUNTIFS($P$26:$P$308,T$1,$D$26:$D$308,$R10) -> 0 | U10: =COUNTIFS($P$26:$P$308,U$1,$D$26:$D$308,$R10) -> 0 | V10: =COUNTIFS($P$26:$P$308,V$1,$D$26:$D$308,$R10) -> 0 | W10: =COUNTIFS($P$26:$P$308,W$1,$D$26:$D$308,$R10) -> 0 | X10: =COUNTIFS($P$26:$P$308,X$1,$D$26:$D$308,$R10) -> 0 | Y10: =COUNTIFS($P$26:$P$308,Y$1,$D$26:$D$308,$R10) -> 0 | Z10: =COUNTIFS($P$26:$P$308,Z$1,$D$26:$D$308,$R10) -> 0 | ... AD10: =COUNTIFS($P$26:$P$308,AD$1,$D$26:$D$308,$R10) -> 0 | AE10: =SUM(S10:AD10) -> 0
E11: El Castaño | F11: =COUNTIFS($N$26:$N$290,1,$C$26:$C$290,$E11) -> 2 | G11: =SUMIFS($K$26:$K$290,$N$26:$N$290,1,$C$26:$C$290,$E11) -> 7 | R11: SPRS | S11: =COUNTIFS($P$26:$P$308,S$1,$D$26:$D$308,$R11) -> 0 | T11: =COUNTIFS($P$26:$P$308,T$1,$D$26:$D$308,$R11) -> 0 | U11: =COUNTIFS($P$26:$P$308,U$1,$D$26:$D$308,$R11) -> 0 | V11: =COUNTIFS($P$26:$P$308,V$1,$D$26:$D$308,$R11) -> 0 | W11: =COUNTIFS($P$26:$P$308,W$1,$D$26:$D$308,$R11) -> 0 | X11: =COUNTIFS($P$26:$P$308,X$1,$D$26:$D$308,$R11) -> 4 | Y11: =COUNTIFS($P$26:$P$308,Y$1,$D$26:$D$308,$R11) -> 0 | Z11: =COUNTIFS($P$26:$P$308,Z$1,$D$26:$D$308,$R11) -> 4 | ... AD11: =COUNTIFS($P$26:$P$308,AD$1,$D$26:$D$308,$R11) -> 0 | AE11: =SUM(S11:AD11) -> 13
E12: Reforma | F12: =COUNTIFS($N$26:$N$290,1,$C$26:$C$290,$E12) -> 2 | G12: =SUMIFS($K$26:$K$290,$N$26:$N$290,1,$C$26:$C$290,$E12) -> 25 | R12: SSSTPA | S12: =COUNTIFS($P$26:$P$308,S$1,$D$26:$D$308,$R12) -> 0 | T12: =COUNTIFS($P$26:$P$308,T$1,$D$26:$D$308,$R12) -> 1 | U12: =COUNTIFS($P$26:$P$308,U$1,$D$26:$D$308,$R12) -> 4 | V12: =COUNTIFS($P$26:$P$308,V$1,$D$26:$D$308,$R12) -> 1 | W12: =COUNTIFS($P$26:$P$308,W$1,$D$26:$D$308,$R12) -> 4 | X12: =COUNTIFS($P$26:$P$308,X$1,$D$26:$D$308,$R12) -> 2 | Y12: =COUNTIFS($P$26:$P$308,Y$1,$D$26:$D$308,$R12) -> 0 | Z12: =COUNTIFS($P$26:$P$308,Z$1,$D$26:$D$308,$R12) -> 12 | ... AD12: =COUNTIFS($P$26:$P$308,AD$1,$D$26:$D$308,$R12) -> 1 | AE12: =SUM(S12:AD12) -> 31
E13: Cunduacán | F13: =COUNTIFS($N$26:$N$290,1,$C$26:$C$290,$E13) -> 3 | G13: =SUMIFS($K$26:$K$290,$N$26:$N$290,1,$C$26:$C$290,$E13) -> 30 | R13: Total | S13: =SUM(S2:S12) -> 0 | T13: =SUM(T2:T12) -> 1 | U13: =SUM(U2:U12) -> 4 | V13: =SUM(V2:V12) -> 1 | W13: =SUM(W2:W12) -> 14 | X13: =SUM(X2:X12) -> 14 | Y13: =SUM(Y2:Y12) -> 0 | Z13: =SUM(Z2:Z12) -> 16 | ... AE13: =SUM(AE2:AE12) -> 63
E14: Villahermosa | F14: =COUNTIFS($N$26:$N$290,1,$C$26:$C$290,$E14) -> 12 | G14: =SUMIFS($K$26:$K$290,$N$26:$N$290,1,$C$26:$C$290,$E14) -> 225
E15: SPMP Tierra | F15: =COUNTIFS($N$26:$N$290,1,$C$26:$C$290,$E15) -> 5 | G15: =SUMIFS($K$26:$K$290,$N$26:$N$290,1,$C$26:$C$290,$E15) -> 31
E16: SPMP_Mar Carmen | F16: =COUNTIFS($N$26:$N$290,1,$C$26:$C$290,$E16) -> 0 | G16: =SUMIFS($K$26:$K$290,$N$26:$N$290,1,$C$26:$C$290,$E16) -> 0
E17: SPMP_Mar DB | F17: =COUNTIFS($N$26:$N$290,1,$C$26:$C$290,$E17) -> 2 | G17: =SUMIFS($K$26:$K$290,$N$26:$N$290,1,$C$26:$C$290,$E17) -> 13
E18: Ciudad del Carmen | F18: =COUNTIFS($N$26:$N$290,1,$C$26:$C$290,$E18) -> 12 | G18: =SUMIFS($K$26:$K$290,$N$26:$N$290,1,$C$26:$C$290,$E18) -> 130
E19: Dos Bocas | F19: =COUNTIFS($N$26:$N$290,1,$C$26:$C$290,$E19) -> 12 | G19: =SUMIFS($K$26:$K$290,$N$26:$N$290,1,$C$26:$C$290,$E19) -> 230
E20: PLOG | F20: =COUNTIFS($N$26:$N$290,1,$D$26:$D$290,$E20) -> 10 | G20: =SUMIFS($K$26:$K$290,$N$26:$N$290,1,$D$26:$D$290,$E20) -> 113
E21: Totales | F21: =SUM(F2:F20) -> 83 | G21: =SUM(G2:G20) -> 1088
C23: Cursos adicionales al PICADE original
A25: Cons | B25: Clave | C25: CASES | D25: Subdirección | E25: Gerencia/Activo | F25: Curso | G25: Tipo de Impartición | H25: Ficha | I25: Instructor | J25: Duración (Horas) | K25: Asistentes Totales | L25: Fecha de Inicio | M25: Fecha de Termino | N25: Periodo | O25: Observaciones | P25: MES
A26: 1 | B26: 50650305 | C26: Villahermosa | D26: SSSTPA | E26: GSPSSPAIP | F26: Concepos Básicos de ARP | G26: Presencial | H26: Externo | I26: =IFERROR((VLOOKUP(H26,Padrón[[Ficha]:[Nombre]],2,FALSE)),"-") -> - | J26: 24 | K26: 17 | L26: 44972 | M26: 44974 | N26: =IF(AND(M26>=$B$3,M26<=$C$3),1,"-") -> 1 | P26: =IF(M26="","0",(MONTH(M26))) -> 2
A27: 2 | B27: 50649861 | C27: Villahermosa | D27: SSSTPA | E27: GSPSSPAIP | F27: Curso PHAST instalaciones terrestres | G27: Presencial | H27: Externo | I27: =IFERROR((VLOOKUP(H27,Padrón[[Ficha]:[Nombre]],2,FALSE)),"-") -> - | J27: 40 | K27: 20 | L27: 44984 | M27: 44988 | N27: =IF(AND(M27>=$B$3,M27<=$C$3),1,"-") -> 1 | P27: =IF(M27="","0",(MONTH(M27))) -> 3
A28: 3 | B28: 50649912 | C28: Ciudad del Carmen | D28: SSSTPA | E28: GSPSSPAIP | F28: Curso Análisis de Capas de Protección LOPA | G28: Presencial | H28: Externo | I28: =IFERROR((VLOOKUP(H28,Padrón[[Ficha]:[Nombre]],2,FALSE)),"-") -> - | J28: 24 | K28: 14 | L28: 44986 | M28: 44988 | N28: =IF(AND(M28>=$B$3,M28<=$C$3),1,"-") -> 1 | P28: =IF(M28="","0",(MONTH(M28))) -> 3
A29: 4 | B29: 50649950 | C29: Ciudad del Carmen | D29: SSSTPA | E29: GSPSSPAIP | F29: Curso PHAST instalaciones marinas | G29: Presencial | H29: Externo | I29: =IFERROR((VLOOKUP(H29,Padrón[[Ficha]:[Nombre]],2,FALSE)),"-") -> - | J29: 40 | K29: 12 | L29: 45012 | M29: 45016 | N29: =IF(AND(M29>=$B$3,M29<=$C$3),1,"-") -> 1 | P29: =IF(M29="","0",(MONTH(M29))) -> 3
A30: 5 | B30: 50650022 | C30: Villahermosa | D30: SSSTPA | E30: GSPSSPAIP | F30: Instrumentación de Proyectos de Mejora de Procesos | G30: Distancia | H30: 495716 | I30: =IFERROR((VLOOKUP(H30,Padrón[[Ficha]:[Nombre]],2,FALSE)),"-") -> ENRIQUE GABRIEL ALVAREZ ALMAZAN | J30: 10 | K30: 19 | L30: 45012 | M30: 45016 | N30: =IF(AND(M30>=$B$3,M30<=$C$3),1,"-") -> 1 | P30: =IF(M30="","0",(MONTH(M30))) -> 3
A31: 6 | B31: 50656014 | C31: Ciudad del Carmen | D31: SSSTPA | E31: GSPSSPAIP | F31: Capacitación en Conceptos Básicos de Análisis de Riesgo de Proceso | G31: Presencial | H31: Externo | I31: =IFERROR((VLOOKUP(H31,Padrón[[Ficha]:[Nombre]],2,FALSE)),"-") -> - | J31: 24 | K31: 11 | L31: 45035 | M31: 45037 | N31: =IF(AND(M31>=$B$3,M31<=$C$3),1,"-") -> 1 | P31: =IF(M31="","0",(MONTH(M31))) -> 4
A32: 7 | B32: 50656016 | C32: Villahermosa | D32: SSSTPA | E32: GSPSSPAIP | F32: Conceptos Básicos de ARP | G32: Presencial | H32: Externo | I32: =IFERROR((VLOOKUP(#REF!,Padrón[[Ficha]:[Nombre]],2,FALSE)),"-") -> - | J32: 24 | K32: 23 | L32: 45056 | M32: 45058 | N32: =IF(AND(M32>=$B$3,M32<=$C$3),1,"-") -> 1 | P32: =IF(M32="","0",(MONTH(M32))) -> 5
A33: 8 | B33: 50656018 | C33: Villahermosa | D33: SSSTPA | E33: GSPSSPAIP | F33: Métodos Cualitativos | G33: Presencial | H33: Externo | I33: =IFERROR((VLOOKUP(H33,Padrón[[Ficha]:[Nombre]],2,FALSE)),"-") -> - | J33: 40 | K33: 21 | L33: 45061 | M33: 45065 | N33: =IF(AND(M33>=$B$3,M33<=$C$3),1,"-") -> 1 | P33: =IF(M33="","0",(MONTH(M33))) -> 5
A34: 9 | B34: 50656019 | C34: Poza Rica | D34: SSSTPA | E34: GSPSSPAIP | F34: Métodos Cualitativos | G34: Presencial | H34: Externo | I34: =IFERROR((VLOOKUP(H34,Padrón[[Ficha]:[Nombre]],2,FALSE)),"-") -> - | J34: 40 | K34: 21 | L34: 45061 | M34: 45065 | N34: =IF(AND(M33>=$B$3,M33<=$C$3),1,"-") -> 1 | P34: =IF(M34="","0",(MONTH(M34))) -> 5
A35: 10 | B35: 50656020 | C35: Ciudad del Carmen | D35: SSSTPA | E35: GSPSSPAIP | F35: Métodos Cualitativos | G35: Presencial | H35: Externo | I35: =IFERROR((VLOOKUP(H35,Padrón[[Ficha]:[Nombre]],2,FALSE)),"-") -> - | J35: 40 | K35: 13 | L35: 45075 | M35: 45079 | N35: =IF(AND(M35>=$B$3,M35<=$C$3),1,"-") -> 1 | P35: =IF(M35="","0",(MONTH(M35))) -> 6
A36: 11 | B36: 50664522 | C36: SPMP_Mar DB | D36: SPMP | E36: GOME | F36: BÁSICO DE SEGURIDAD (BS) | G36: Presencial | H36: 384599 | I36: =IFERROR((VLOOKUP(H36,Padrón[[Ficha]:[Nombre]],2,FALSE)),"-") -> MARLON DANIEL MARTINEZ COBA | J36: 16 | K36: 6 | L36: 45049 | M36: 45050 | N36: =IF(AND(M36>=$B$3,M36<=$C$3),1,"-") -> 1 | P36: =IF(M36="","0",(MONTH(M36))) -> 5
A37: 12 | B37: 50664523 | C37: SPMP_Mar DB | D37: SPMP | E37: GOME | F37: BÁSICO DE SEGURIDAD (BS) | G37: Presencial | H37: 384599 | I37: =IFERROR((VLOOKUP(H37,Padrón[[Ficha]:[Nombre]],2,FALSE)),"-") -> MARLON DANIEL MARTINEZ COBA | J37: 16 | K37: 7 | L37: 45055 | M37: 45056 | N37: =IF(AND(M37>=$B$3,M37<=$C$3),1,"-") -> 1 | P37: =IF(M37="","0",(MONTH(M37))) -> 5
A38: 13 | B38: 50655529 | C38: SPMP Tierra | D38: SPMP | E38: GSSTPAP | F38: PROCEDIMIENTOS CRÍTICOS (PC) | G38: Presencial | I38: =IFERROR((VLOOKUP(H38,Padrón[[Ficha]:[Nombre]],2,FALSE)),"-") -> - | K38: 4 | L38: 45051 | M38: 45052 | N38: =IF(AND(M38>=$B$3,M38<=$C$3),1,"-") -> 1 | P38: =IF(M38="","0",(MONTH(M38))) -> 5
A39: 14 | B39: 50655530 | C39: SPMP Tierra | D39: SPMP | E39: GSSTPAP | F39: PROCEDIMIENTOS CRÍTICOS (PC) | G39: Presencial | I39: =IFERROR((VLOOKUP(H39,Padrón[[Ficha]:[Nombre]],2,FALSE)),"-") -> - | K39: 4 | L39: 45054 | M39: 45055 | N39: =IF(AND(M39>=$B$3,M39<=$C$3),1,"-") -> 1 | P39: =IF(M39="","0",(MONTH(M39))) -> 5
A40: 15 | B40: 50655056 | C40: SPMP Tierra | D40: SPMP | E40: GSSTPAP | F40: PROCEDIMIENTO TÉCNICO OPERATIVO ANÁLISIS DE SEGURIDAD AST | G40: Presencial | I40: =IFERROR((VLOOKUP(H40,Padrón[[Ficha]:[Nombre]],2,FALSE)),"-") -> - | K40: 10 | L40: 45048 | M40: 45049 | N40: =IF(AND(M40>=$B$3,M40<=$C$3),1,"-") -> 1 | P40: =IF(M40="","0",(MONTH(M40))) -> 5
A41: 16 | B41: 50655058 | C41: SPMP Tierra | D41: SPMP | E41: GSSTPAP | F41: PROCEDIMIENTO TÉCNICO OPERATIVO ANÁLISIS DE SEGURIDAD AST | G41: Presencial | I41: =IFERROR((VLOOKUP(H41,Padrón[[Ficha]:[Nombre]],2,FALSE)),"-") -> - | K41: 6 | L41: 45054 | M41: 45055 | N41: =IF(AND(M41>=$B$3,M41<=$C$3),1,"-") -> 1 | P41: =IF(M41="","0",(MONTH(M41))) -> 5
A42: 17 | B42: 50655065 | C42: SPMP Tierra | D42: SPMP | E42: GSSTPAP | F42: PROCEDIMIENTO TÉCNICO OPERATIVO ANÁLISIS DE SEGURIDAD AST | G42: Presencial | I42: =IFERROR((VLOOKUP(H42,Padrón[[Ficha]:[Nombre]],2,FALSE)),"-") -> - | K42: 7 | L42: 45057 | M42: 45058 | N42: =IF(AND(M42>=$B$3,M42<=$C$3),1,"-") -> 1 | P42: =IF(M42="","0",(MONTH(M42))) -> 5
...

Sheet Hoja20
C6: Realizado | F6: Reynosa | H6: SCOC
C7: Diferido | F7: Altamira | H7: SE
C8: Cancelado | F8: Naranjos | H8: SEPCA
F9: Cerro Azul | H9: SMLIC
F10: Poza Rica | H10: SPEE
F11: Veracruz | H11: SPMP
F12: Cd. Madero | H12: SPRMNE
F13: Agua Dulce | H13: SPRMSO
F14: Comalcalco | H14: PLOG
F15: El Castaño | H15: SPRN
F16: Reforma | H16: SPRS
F17: Cunduacán | H17: SSSTPA
F18: Villahermosa
F19: SPMP_Mar Carmen
F20: SPMP_Mar DB
F21: SPMP Tierra
F22: Dos Bocas
F23: Ciudad del Carmen

Sheet Reynosa
B1: Fecha inicial | C1: Fecha final | U1: Programa | V1: 1 | W1: 2 | X1: 3 | Y1: 4 | Z1: 5 | AA1: 6 | AB1: 7 | AC1: 8 | AD1: 9 | AE1: 10 | AF1: 11 | AG1: 12 | AH1: Total
B2: =Seguimiento!$E$6 -> 44927 | C2: =Seguimiento!$J$6 -> 45291 | U2: SCOC | V2: =COUNTIFS($L$14:$L$300,V$1,$C$14:$C$300,$U2) -> 0 | W2: =COUNTIFS($L$14:$L$300,W$1,$C$14:$C$300,$U2) -> 0 | X2: =COUNTIFS($L$14:$L$300,X$1,$C$14:$C$300,$U2) -> 0 | Y2: =COUNTIFS($L$14:$L$300,Y$1,$C$14:$C$300,$U2) -> 0 | Z2: =COUNTIFS($L$14:$L$300,Z$1,$C$14:$C$300,$U2) -> 0 | AA2: =COUNTIFS($L$14:$L$300,AA$1,$C$14:$C$300,$U2) -> 0 | AB2: =COUNTIFS($L$14:$L$300,AB$1,$C$14:$C$300,$U2) -> 0 | AC2: =COUNTIFS($L$14:$L$300,AC$1,$C$14:$C$300,$U2) -> 0 | ... AG2: =COUNTIFS($L$14:$L$300,AG$1,$C$14:$C$300,$U2) -> 0 | AH2: =SUM(V2:AG2) -> 0
H3: PICADE | U3: SE | V3: =COUNTIFS($L$14:$L$300,V$1,$C$14:$C$300,$U3) -> 0 | W3: =COUNTIFS($L$14:$L$300,W$1,$C$14:$C$300,$U3) -> 0 | X3: =COUNTIFS($L$14:$L$300,X$1,$C$14:$C$300,$U3) -> 0 | Y3: =COUNTIFS($L$14:$L$300,Y$1,$C$14:$C$300,$U3) -> 0 | Z3: =COUNTIFS($L$14:$L$300,Z$1,$C$14:$C$300,$U3) -> 0 | AA3: =COUNTIFS($L$14:$L$300,AA$1,$C$14:$C$300,$U3) -> 0 | AB3: =COUNTIFS($L$14:$L$300,AB$1,$C$14:$C$300,$U3) -> 0 | AC3: =COUNTIFS($L$14:$L$300,AC$1,$C$14:$C$300,$U3) -> 0 | ... AG3: =COUNTIFS($L$14:$L$300,AG$1,$C$14:$C$300,$U3) -> 0 | AH3: =SUM(V3:AG3) -> 0
H4: Cursos | I4: Capacitandos | J4: Cursos Programados | K4: Realizados en prog. | L4: Cancelados | N4: Capacitandos programados | O4: Capacitandos | U4: SEPCA | V4: =COUNTIFS($L$14:$L$300,V$1,$C$14:$C$300,$U4) -> 0 | W4: =COUNTIFS($L$14:$L$300,W$1,$C$14:$C$300,$U4) -> 0 | X4: =COUNTIFS($L$14:$L$300,X$1,$C$14:$C$300,$U4) -> 0 | Y4: =COUNTIFS($L$14:$L$300,Y$1,$C$14:$C$300,$U4) -> 0 | Z4: =COUNTIFS($L$14:$L$300,Z$1,$C$14:$C$300,$U4) -> 0 | AA4: =COUNTIFS($L$14:$L$300,AA$1,$C$14:$C$300,$U4) -> 0 | AB4: =COUNTIFS($L$14:$L$300,AB$1,$C$14:$C$300,$U4) -> 0 | AC4: =COUNTIFS($L$14:$L$300,AC$1,$C$14:$C$300,$U4) -> 0 | ... AG4: =COUNTIFS($L$14:$L$300,AG$1,$C$14:$C$300,$U4) -> 0 | AH4: =SUM(V4:AG4) -> 0
H5: =COUNT(A14:A300) -> 66 | I5: =SUM(H14:H300) -> 869 | J5: =COUNTIF($M$14:$M$300,1) -> 66 | K5: =COUNTIFS($M$14:$M$300,1,$N$14:$N$300,"Realizado") -> 66 | L5: =COUNTIFS($M$14:$M$300,1,$N$14:$N$300,"Cancelado") -> 0 | N5: =+SUMIF($M$14:$M$300,1,$H$14:$H$300) -> 869 | O5: =+SUMIF($M$14:$M$300,1,$O$14:$O$300) -> 825 | U5: SMLIC | V5: =COUNTIFS($L$14:$L$300,V$1,$C$14:$C$300,$U5) -> 0 | W5: =COUNTIFS($L$14:$L$300,W$1,$C$14:$C$300,$U5) -> 0 | X5: =COUNTIFS($L$14:$L$300,X$1,$C$14:$C$300,$U5) -> 0 | Y5: =COUNTIFS($L$14:$L$300,Y$1,$C$14:$C$300,$U5) -> 0 | Z5: =COUNTIFS($L$14:$L$300,Z$1,$C$14:$C$300,$U5) -> 0 | AA5: =COUNTIFS($L$14:$L$300,AA$1,$C$14:$C$300,$U5) -> 5 | AB5: =COUNTIFS($L$14:$L$300,AB$1,$C$14:$C$300,$U5) -> 0 | AC5: =COUNTIFS($L$14:$L$300,AC$1,$C$14:$C$300,$U5) -> 0 | ... AG5: =COUNTIFS($L$14:$L$300,AG$1,$C$14:$C$300,$U5) -> 0 | AH5: =SUM(V5:AG5) -> 7
U6: SPEE | V6: =COUNTIFS($L$14:$L$300,V$1,$C$14:$C$300,$U6) -> 0 | W6: =COUNTIFS($L$14:$L$300,W$1,$C$14:$C$300,$U6) -> 0 | X6: =COUNTIFS($L$14:$L$300,X$1,$C$14:$C$300,$U6) -> 0 | Y6: =COUNTIFS($L$14:$L$300,Y$1,$C$14:$C$300,$U6) -> 0 | Z6: =COUNTIFS($L$14:$L$300,Z$1,$C$14:$C$300,$U6) -> 0 | AA6: =COUNTIFS($L$14:$L$300,AA$1,$C$14:$C$300,$U6) -> 0 | AB6: =COUNTIFS($L$14:$L$300,AB$1,$C$14:$C$300,$U6) -> 0 | AC6: =COUNTIFS($L$14:$L$300,AC$1,$C$14:$C$300,$U6) -> 0 | ... AG6: =COUNTIFS($L$14:$L$300,AG$1,$C$14:$C$300,$U6) -> 0 | AH6: =SUM(V6:AG6) -> 0
U7: SPMP | V7: =COUNTIFS($L$14:$L$300,V$1,$C$14:$C$300,$U7) -> 0 | W7: =COUNTIFS($L$14:$L$300,W$1,$C$14:$C$300,$U7) -> 0 | X7: =COUNTIFS($L$14:$L$300,X$1,$C$14:$C$300,$U7) -> 0 | Y7: =COUNTIFS($L$14:$L$300,Y$1,$C$14:$C$300,$U7) -> 0 | Z7: =COUNTIFS($L$14:$L$300,Z$1,$C$14:$C$300,$U7) -> 0 | AA7: =COUNTIFS($L$14:$L$300,AA$1,$C$14:$C$300,$U7) -> 0 | AB7: =COUNTIFS($L$14:$L$300,AB$1,$C$14:$C$300,$U7) -> 0 | AC7: =COUNTIFS($L$14:$L$300,AC$1,$C$14:$C$300,$U7) -> 0 | ... AG7: =COUNTIFS($L$14:$L$300,AG$1,$C$14:$C$300,$U7) -> 0 | AH7: =SUM(V7:AG7) -> 0
U8: SPRMNE | V8: =COUNTIFS($L$14:$L$300,V$1,$C$14:$C$300,$U8) -> 0 | W8: =COUNTIFS($L$14:$L$300,W$1,$C$14:$C$300,$U8) -> 0 | X8: =COUNTIFS($L$14:$L$300,X$1,$C$14:$C$300,$U8) -> 0 | Y8: =COUNTIFS($L$14:$L$300,Y$1,$C$14:$C$300,$U8) -> 0 | Z8: =COUNTIFS($L$14:$L$300,Z$1,$C$14:$C$300,$U8) -> 0 | AA8: =COUNTIFS($L$14:$L$300,AA$1,$C$14:$C$300,$U8) -> 0 | AB8: =COUNTIFS($L$14:$L$300,AB$1,$C$14:$C$300,$U8) -> 0 | AC8: =COUNTIFS($L$14:$L$300,AC$1,$C$14:$C$300,$U8) -> 0 | ... AG8: =COUNTIFS($L$14:$L$300,AG$1,$C$14:$C$300,$U8) -> 0 | AH8: =SUM(V8:AG8) -> 0
U9: SPRMSO | V9: =COUNTIFS($L$14:$L$300,V$1,$C$14:$C$300,$U9) -> 0 | W9: =COUNTIFS($L$14:$L$300,W$1,$C$14:$C$300,$U9) -> 0 | X9: =COUNTIFS($L$14:$L$300,X$1,$C$14:$C$300,$U9) -> 0 | Y9: =COUNTIFS($L$14:$L$300,Y$1,$C$14:$C$300,$U9) -> 0 | Z9: =COUNTIFS($L$14:$L$300,Z$1,$C$14:$C$300,$U9) -> 0 | AA9: =COUNTIFS($L$14:$L$300,AA$1,$C$14:$C$300,$U9) -> 0 | AB9: =COUNTIFS($L$14:$L$300,AB$1,$C$14:$C$300,$U9) -> 0 | AC9: =COUNTIFS($L$14:$L$300,AC$1,$C$14:$C$300,$U9) -> 0 | ... AG9: =COUNTIFS($L$14:$L$300,AG$1,$C$14:$C$300,$U9) -> 0 | AH9: =SUM(V9:AG9) -> 0
U10: SPRN | V10: =COUNTIFS($L$14:$L$300,V$1,$C$14:$C$300,$U10) -> 0 | W10: =COUNTIFS($L$14:$L$300,W$1,$C$14:$C$300,$U10) -> 1 | X10: =COUNTIFS($L$14:$L$300,X$1,$C$14:$C$300,$U10) -> 4 | Y10: =COUNTIFS($L$14:$L$300,Y$1,$C$14:$C$300,$U10) -> 8 | Z10: =COUNTIFS($L$14:$L$300,Z$1,$C$14:$C$300,$U10) -> 13 | AA10: =COUNTIFS($L$14:$L$300,AA$1,$C$14:$C$300,$U10) -> 9 | AB10: =COUNTIFS($L$14:$L$300,AB$1,$C$14:$C$300,$U10) -> 0 | AC10: =COUNTIFS($L$14:$L$300,AC$1,$C$14:$C$300,$U10) -> 1 | ... AG10: =COUNTIFS($L$14:$L$300,AG$1,$C$14:$C$300,$U10) -> 0 | AH10: =SUM(V10:AG10) -> 50
U11: SPRS | V11: =COUNTIFS($L$14:$L$300,V$1,$C$14:$C$300,$U11) -> 0 | W11: =COUNTIFS($L$14:$L$300,W$1,$C$14:$C$300,$U11) -> 0 | X11: =COUNTIFS($L$14:$L$300,X$1,$C$14:$C$300,$U11) -> 0 | Y11: =COUNTIFS($L$14:$L$300,Y$1,$C$14:$C$300,$U11) -> 0 | Z11: =COUNTIFS($L$14:$L$300,Z$1,$C$14:$C$300,$U11) -> 0 | AA11: =COUNTIFS($L$14:$L$300,AA$1,$C$14:$C$300,$U11) -> 0 | AB11: =COUNTIFS($L$14:$L$300,AB$1,$C$14:$C$300,$U11) -> 0 | AC11: =COUNTIFS($L$14:$L$300,AC$1,$C$14:$C$300,$U11) -> 0 | ... AG11: =COUNTIFS($L$14:$L$300,AG$1,$C$14:$C$300,$U11) -> 0 | AH11: =SUM(V11:AG11) -> 0
U12: SSSTPA | V12: =COUNTIFS($L$14:$L$300,V$1,$C$14:$C$300,$U12) -> 0 | W12: =COUNTIFS($L$14:$L$300,W$1,$C$14:$C$300,$U12) -> 0 | X12: =COUNTIFS($L$14:$L$300,X$1,$C$14:$C$300,$U12) -> 0 | Y12: =COUNTIFS($L$14:$L$300,Y$1,$C$14:$C$300,$U12) -> 0 | Z12: =COUNTIFS($L$14:$L$300,Z$1,$C$14:$C$300,$U12) -> 4 | AA12: =COUNTIFS($L$14:$L$300,AA$1,$C$14:$C$300,$U12) -> 5 | AB12: =COUNTIFS($L$14:$L$300,AB$1,$C$14:$C$300,$U12) -> 0 | AC12: =COUNTIFS($L$14:$L$300,AC$1,$C$14:$C$300,$U12) -> 0 | ... AG12: =COUNTIFS($L$14:$L$300,AG$1,$C$14:$C$300,$U12) -> 0 | AH12: =SUM(V12:AG12) -> 9
A13: IDSDNCA | B13: IDSAP | C13: Subdirección | D13: Gerencia/Activo | E13: Nombre Evento Original | F13: Ficha Instructor | G13: Nombre Instructor | H13: Asistentes Programados | I13: Fecha de Inicio | J13: Fecha de Termino | K13: Sede | L13: Mes | M13: Periodo | N13: Estatus curso | O13: Capacitandos | P13: Ficha Inst | Q13: Instructor | R13: Observaciones | U13: Total | V13: =SUM(V2:V12) -> 0 | W13: =SUM(W2:W12) -> 1 | X13: =SUM(X2:X12) -> 4 | Y13: =SUM(Y2:Y12) -> 8 | Z13: =SUM(Z2:Z12) -> 17 | AA13: =SUM(AA2:AA12) -> 19 | AB13: =SUM(AB2:AB12) -> 0 | AC13: =SUM(AC2:AC12) -> 1 | ... AH13: =SUM(AH2:AH12) -> 66
A14: 52339 | C14: SPRN | D14: ACTIVO DE PRODUCCIÓN REYNOSA | E14: SEGURIDAD EN CENTROS ADMINISTRATIVOS (SCA) | F14: 375324 | G14: MADRIGAL ELISEO DAVID MICHAEL | H14: 12 | I14: 44958 | J14: 44958 | K14: REYNOSA, TAMAULIPAS | L14: =MONTH(J14) -> 2 | M14: =IF(AND(J14>=$B$2,J14<=$C$2),1,0) -> 1 | N14: Realizado | O14: 12 | P14: 375324 | Q14: =IFERROR((VLOOKUP(P14,Padrón[[Ficha]:[Nombre]],2,FALSE)),"-") -> DAVID MICHAEL MADRIGAL ELISEO | S14: =IF(N14="Cancelado","◄ ◄ ◄ Favor de indicar la causa","-") -> -
A15: 52298 | C15: SPRN | D15: ACTIVO DE PRODUCCIÓN REYNOSA | E15: BÁSICO DE SEGURIDAD (BS) | F15: 196157 | G15: POSADAS RAMÍREZ LUCIO ALFONSO | H15: 14 | I15: 44992 | J15: 44993 | K15: REYNOSA, TAMAULIPAS | L15: =MONTH(J15) -> 3 | M15: =IF(AND(J15>=$B$2,J15<=$C$2),1,0) -> 1 | N15: Realizado | O15: 13 | P15: 375324 | Q15: =IFERROR((VLOOKUP(P15,Padrón[[Ficha]:[Nombre]],2,FALSE)),"-") -> DAVID MICHAEL MADRIGAL ELISEO | S15: =IF(N15="Cancelado","◄ ◄ ◄ Favor de indicar la causa","-") -> - | U15: Realizados | V15: 1 | W15: 2 | X15: 3 | Y15: 4 | Z15: 5 | AA15: 6 | AB15: 7 | AC15: 8 | AD15: 9 | AE15: 10 | AF15: 11 | AG15: 12 | AH15: Total
A16: 57979 | C16: SPRN | D16: ACTIVO DE PRODUCCIÓN REYNOSA | E16: PREVENCIÓN DE RIESGOS LABORALES (PRL) | F16: 196157 | G16: POSADAS RAMÍREZ LUCIO ALFONSO | H16: 14 | I16: 45006 | J16: 45009 | K16: REYNOSA, TAMAULIPAS | L16: =MONTH(J16) -> 3 | M16: =IF(AND(J16>=$B$2,J16<=$C$2),1,0) -> 1 | N16: Realizado | O16: 14 | P16: 196157 | Q16: =IFERROR((VLOOKUP(P16,Padrón[[Ficha]:[Nombre]],2,FALSE)),"-") -> LUCIO ALFONSO POSADAS RAMIREZ | S16: =IF(N16="Cancelado","◄ ◄ ◄ Favor de indicar la causa","-") -> - | U16: SCOC | V16: =COUNTIFS($L$14:$L$300,V$15,$C$14:$C$300,$U16,$N$14:$N$300,"Realizado") -> 0 | W16: =COUNTIFS($L$14:$L$300,W$15,$C$14:$C$300,$U16,$N$14:$N$300,"Realizado") -> 0 | X16: =COUNTIFS($L$14:$L$300,X$15,$C$14:$C$300,$U16,$N$14:$N$300,"Realizado") -> 0 | Y16: =COUNTIFS($L$14:$L$300,Y$15,$C$14:$C$300,$U16,$N$14:$N$300,"Realizado") -> 0 | Z16: =COUNTIFS($L$14:$L$300,Z$15,$C$14:$C$300,$U16,$N$14:$N$300,"Realizado") -> 0 | AA16: =COUNTIFS($L$14:$L$300,AA$15,$C$14:$C$300,$U16,$N$14:$N$300,"Realizado") -> 0 | AB16: =COUNTIFS($L$14:$L$300,AB$15,$C$14:$C$300,$U16,$N$14:$N$300,"Realizado") -> 0 | AC16: =COUNTIFS($L$14:$L$300,AC$15,$C$14:$C$300,$U16,$N$14:$N$300,"Realizado") -> 0 | ... AG16: =COUNTIFS($L$14:$L$300,AG$15,$C$14:$C$300,$U16,$N$14:$N$300,"Realizado") -> 0 | AH16: =SUM(V16:AG16) -> 0
A17: 60088 | C17: SPRN | D17: ACTIVO DE PRODUCCIÓN REYNOSA | E17: BÁSICO DE SEGURIDAD (BS) | F17: 196157 | G17: POSADAS RAMÍREZ LUCIO ALFONSO | H17: 8 | I17: 45012 | J17: 45013 | K17: REYNOSA, TAMAULIPAS | L17: =MONTH(J17) -> 3 | M17: =IF(AND(J17>=$B$2,J17<=$C$2),1,0) -> 1 | N17: Realizado | O17: 7 | P17: 196157 | Q17: =IFERROR((VLOOKUP(P17,Padrón[[Ficha]:[Nombre]],2,FALSE)),"-") -> LUCIO ALFONSO POSADAS RAMIREZ | S17: =IF(N17="Cancelado","◄ ◄ ◄ Favor de indicar la causa","-") -> - | U17: SE | V17: =COUNTIFS($L$14:$L$300,V$15,$C$14:$C$300,$U17,$N$14:$N$300,"Realizado") -> 0 | W17: =COUNTIFS($L$14:$L$300,W$15,$C$14:$C$300,$U17,$N$14:$N$300,"Realizado") -> 0 | X17: =COUNTIFS($L$14:$L$300,X$15,$C$14:$C$300,$U17,$N$14:$N$300,"Realizado") -> 0 | Y17: =COUNTIFS($L$14:$L$300,Y$15,$C$14:$C$300,$U17,$N$14:$N$300,"Realizado") -> 0 | Z17: =COUNTIFS($L$14:$L$300,Z$15,$C$14:$C$300,$U17,$N$14:$N$300,"Realizado") -> 0 | AA17: =COUNTIFS($L$14:$L$300,AA$15,$C$14:$C$300,$U17,$N$14:$N$300,"Realizado") -> 0 | AB17: =COUNTIFS($L$14:$L$300,AB$15,$C$14:$C$300,$U17,$N$14:$N$300,"Realizado") -> 0 | AC17: =COUNTIFS($L$14:$L$300,AC$15,$C$14:$C$300,$U17,$N$14:$N$300,"Realizado") -> 0 | ... AG17: =COUNTIFS($L$14:$L$300,AG$15,$C$14:$C$300,$U17,$N$14:$N$300,"Realizado") -> 0 | AH17: =SUM(V17:AG17) -> 0
A18: 52040 | C18: SPRN | D18: ACTIVO DE PRODUCCIÓN REYNOSA | E18: BRIGADAS DE PRIMEROS AUXILIOS (BPA) | F18: 228486 | G18: HERNANDEZ GALVAN JORGE EDUARDO | H18: 16 | I18: 45014 | J18: 45015 | K18: REYNOSA, TAMAULIPAS | L18: =MONTH(J18) -> 3 | M18: =IF(AND(J18>=$B$2,J18<=$C$2),1,0) -> 1 | N18: Realizado | O18: 17 | P18: 228486 | Q18: =IFERROR((VLOOKUP(P18,Padrón[[Ficha]:[Nombre]],2,FALSE)),"-") -> JORGE EDUARDO HERNANDEZ GALVAN | S18: =IF(N18="Cancelado","◄ ◄ ◄ Favor de indicar la causa","-") -> - | U18: SEPCA | V18: =COUNTIFS($L$14:$L$300,V$15,$C$14:$C$300,$U18,$N$14:$N$300,"Realizado") -> 0 | W18: =COUNTIFS($L$14:$L$300,W$15,$C$14:$C$300,$U18,$N$14:$N$300,"Realizado") -> 0 | X18: =COUNTIFS($L$14:$L$300,X$15,$C$14:$C$300,$U18,$N$14:$N$300,"Realizado") -> 0 | Y18: =COUNTIFS($L$14:$L$300,Y$15,$C$14:$C$300,$U18,$N$14:$N$300,"Realizado") -> 0 | Z18: =COUNTIFS($L$14:$L$300,Z$15,$C$14:$C$300,$U18,$N$14:$N$300,"Realizado") -> 0 | AA18: =COUNTIFS($L$14:$L$300,AA$15,$C$14:$C$300,$U18,$N$14:$N$300,"Realizado") -> 0 | AB18: =COUNTIFS($L$14:$L$300,AB$15,$C$14:$C$300,$U18,$N$14:$N$300,"Realizado") -> 0 | AC18: =COUNTIFS($L$14:$L$300,AC$15,$C$14:$C$300,$U18,$N$14:$N$300,"Realizado") -> 0 | ... AG18: =COUNTIFS($L$14:$L$300,AG$15,$C$14:$C$300,$U18,$N$14:$N$300,"Realizado") -> 0 | AH18: =SUM(V18:AG18) -> 0
A19: 52471 | C19: SPRN | D19: ACTIVO DE PRODUCCIÓN REYNOSA | E19: REACREDITACIÓN DE SIGNATARIOS DEL SPPTR (RSPTR) | F19: 196157 | G19: POSADAS RAMÍREZ LUCIO ALFONSO | H19: 10 | I19: 45019 | J19: 45019 | K19: REYNOSA, TAMAULIPAS | L19: =MONTH(J19) -> 4 | M19: =IF(AND(J19>=$B$2,J19<=$C$2),1,0) -> 1 | N19: Realizado | O19: 9 | P19: 196157 | Q19: =IFERROR((VLOOKUP(P19,Padrón[[Ficha]:[Nombre]],2,FALSE)),"-") -> LUCIO ALFONSO POSADAS RAMIREZ | S19: =IF(N19="Cancelado","◄ ◄ ◄ Favor de indicar la causa","-") -> - | U19: SMLIC | V19: =COUNTIFS($L$14:$L$300,V$15,$C$14:$C$300,$U19,$N$14:$N$300,"Realizado") -> 0 | W19: =COUNTIFS($L$14:$L$300,W$15,$C$14:$C$300,$U19,$N$14:$N$300,"Realizado") -> 0 | X19: =COUNTIFS($L$14:$L$300,X$15,$C$14:$C$300,$U19,$N$14:$N$300,"Realizado") -> 0 | Y19: =COUNTIFS($L$14:$L$300,Y$15,$C$14:$C$300,$U19,$N$14:$N$300,"Realizado") -> 0 | Z19: =COUNTIFS($L$14:$L$300,Z$15,$C$14:$C$300,$U19,$N$14:$N$300,"Realizado") -> 0 | AA19: =COUNTIFS($L$14:$L$300,AA$15,$C$14:$C$300,$U19,$N$14:$N$300,"Realizado") -> 5 | AB19: =COUNTIFS($L$14:$L$300,AB$15,$C$14:$C$300,$U19,$N$14:$N$300,"Realizado") -> 0 | AC19: =COUNTIFS($L$14:$L$300,AC$15,$C$14:$C$300,$U19,$N$14:$N$300,"Realizado") -> 0 | ... AG19: =COUNTIFS($L$14:$L$300,AG$15,$C$14:$C$300,$U19,$N$14:$N$300,"Realizado") -> 0 | AH19: =SUM(V19:AG19) -> 7
A20: 52462 | C20: SPRN | D20: ACTIVO DE PRODUCCIÓN REYNOSA | E20: REACREDITACIÓN DE SIGNATARIOS DEL SPPTR (RSPTR) | F20: 196157 | G20: POSADAS RAMÍREZ LUCIO ALFONSO | H20: 13 | I20: 45026 | J20: 45026 | K20: REYNOSA, TAMAULIPAS | L20: =MONTH(J20) -> 4 | M20: =IF(AND(J20>=$B$2,J20<=$C$2),1,0) -> 1 | N20: Realizado | O20: 12 | P20: 196157 | Q20: =IFERROR((VLOOKUP(P20,Padrón[[Ficha]:[Nombre]],2,FALSE)),"-") -> LUCIO ALFONSO POSADAS RAMIREZ | S20: =IF(N20="Cancelado","◄ ◄ ◄ Favor de indicar la causa","-") -> - | U20: SPEE | V20: =COUNTIFS($L$14:$L$300,V$15,$C$14:$C$300,$U20,$N$14:$N$300,"Realizado") -> 0 | W20: =COUNTIFS($L$14:$L$300,W$15,$C$14:$C$300,$U20,$N$14:$N$300,"Realizado") -> 0 | X20: =COUNTIFS($L$14:$L$300,X$15,$C$14:$C$300,$U20,$N$14:$N$300,"Realizado") -> 0 | Y20: =COUNTIFS($L$14:$L$300,Y$15,$C$14:$C$300,$U20,$N$14:$N$300,"Realizado") -> 0 | Z20: =COUNTIFS($L$14:$L$300,Z$15,$C$14:$C$300,$U20,$N$14:$N$300,"Realizado") -> 0 | AA20: =COUNTIFS($L$14:$L$300,AA$15,$C$14:$C$300,$U20,$N$14:$N$300,"Realizado") -> 0 | AB20: =COUNTIFS($L$14:$L$300,AB$15,$C$14:$C$300,$U20,$N$14:$N$300,"Realizado") -> 0 | AC20: =COUNTIFS($L$14:$L$300,AC$15,$C$14:$C$300,$U20,$N$14:$N$300,"Realizado") -> 0 | ... AG20: =COUNTIFS($L$14:$L$300,AG$15,$C$14:$C$300,$U20,$N$14:$N$300,"Realizado") -> 0 | AH20: =SUM(V20:AG20) -> 0
A21: 52266 | C21: SPRN | D21: ACTIVO DE PRODUCCIÓN REYNOSA | E21: ÁCIDO SULFHÍDRICO (H2S) | F21: 361575 | G21: BRIZUELA JASSO JOSE ENRIQUE | H21: 9 | I21: 45027 | J21: 45027 | K21: REYNOSA, TAMAULIPAS | L21: =MONTH(J21) -> 4 | M21: =IF(AND(J21>=$B$2,J21<=$C$2),1,0) -> 1 | N21: Realizado | O21: 9 | P21: 361575 | Q21: =IFERROR((VLOOKUP(P21,Padrón[[Ficha]:[Nombre]],2,FALSE)),"-") -> JOSE ENRIQUE BRIZUELA JASSO | S21: =IF(N21="Cancelado","◄ ◄ ◄ Favor de indicar la causa","-") -> - | U21: SPMP | V21: =COUNTIFS($L$14:$L$300,V$15,$C$14:$C$300,$U21,$N$14:$N$300,"Realizado") -> 0 | W21: =COUNTIFS($L$14:$L$300,W$15,$C$14:$C$300,$U21,$N$14:$N$300,"Realizado") -> 0 | X21: =COUNTIFS($L$14:$L$300,X$15,$C$14:$C$300,$U21,$N$14:$N$300,"Realizado") -> 0 | Y21: =COUNTIFS($L$14:$L$300,Y$15,$C$14:$C$300,$U21,$N$14:$N$300,"Realizado") -> 0 | Z21: =COUNTIFS($L$14:$L$300,Z$15,$C$14:$C$300,$U21,$N$14:$N$300,"Realizado") -> 0 | AA21: =COUNTIFS($L$14:$L$300,AA$15,$C$14:$C$300,$U21,$N$14:$N$300,"Realizado") -> 0 | AB21: =COUNTIFS($L$14:$L$300,AB$15,$C$14:$C$300,$U21,$N$14:$N$300,"Realizado") -> 0 | AC21: =COUNTIFS($L$14:$L$300,AC$15,$C$14:$C$300,$U21,$N$14:$N$300,"Realizado") -> 0 | ... AG21: =COUNTIFS($L$14:$L$300,AG$15,$C$14:$C$300,$U21,$N$14:$N$300,"Realizado") -> 0 | AH21: =SUM(V21:AG21) -> 0
A22: 47728 | C22: SPRN | D22: ACTIVO DE PRODUCCIÓN REYNOSA | E22: DISCIPLINA OPERATIVA (DO) | F22: 196157 | G22: POSADAS RAMÍREZ LUCIO ALFONSO | H22: 17 | I22: 45029 | J22: 45030 | K22: REYNOSA, TAMAULIPAS | L22: =MONTH(J22) -> 4 | M22: =IF(AND(J22>=$B$2,J22<=$C$2),1,0) -> 1 | N22: Realizado | O22: 15 | P22: 196157 | Q22: =IFERROR((VLOOKUP(P22,Padrón[[Ficha]:[Nombre]],2,FALSE)),"-") -> LUCIO ALFONSO POSADAS RAMIREZ | S22: =IF(N22="Cancelado","◄ ◄ ◄ Favor de indicar la causa","-") -> - | U22: SPRMNE | V22: =COUNTIFS($L$14:$L$300,V$15,$C$14:$C$300,$U22,$N$14:$N$300,"Realizado") -> 0 | W22: =COUNTIFS($L$14:$L$300,W$15,$C$14:$C$300,$U22,$N$14:$N$300,"Realizado") -> 0 | X22: =COUNTIFS($L$14:$L$300,X$15,$C$14:$C$300,$U22,$N$14:$N$300,"Realizado") -> 0 | Y22: =COUNTIFS($L$14:$L$300,Y$15,$C$14:$C$300,$U22,$N$14:$N$300,"Realizado") -> 0 | Z22: =COUNTIFS($L$14:$L$300,Z$15,$C$14:$C$300,$U22,$N$14:$N$300,"Realizado") -> 0 | AA22: =COUNTIFS($L$14:$L$300,AA$15,$C$14:$C$300,$U22,$N$14:$N$300,"Realizado") -> 0 | AB22: =COUNTIFS($L$14:$L$300,AB$15,$C$14:$C$300,$U22,$N$14:$N$300,"Realizado") -> 0 | AC22: =COUNTIFS($L$14:$L$300,AC$15,$C$14:$C$300,$U22,$N$14:$N$300,"Realizado") -> 0 | ... AG22: =COUNTIFS($L$14:$L$300,AG$15,$C$14:$C$300,$U22,$N$14:$N$300,"Realizado") -> 0 | AH22: =SUM(V22:AG22) -> 0
A23: 47010 | C23: SPRN | D23: GERENCIA DE MANTENIMIENTO, CONFIABILIDAD Y CONSTRUCCIÓN | E23: BÁSICO DE SEGURIDAD (BS) | F23: 196157 | G23: POSADAS RAMÍREZ LUCIO ALFONSO | H23: 10 | I23: 45033 | J23: 45034 | K23: REYNOSA, TAMAULIPAS | L23: =MONTH(J23) -> 4 | M23: =IF(AND(J23>=$B$2,J23<=$C$2),1,0) -> 1 | N23: Realizado | O23: 11 | P23: 196157 | Q23: =IFERROR((VLOOKUP(P23,Padrón[[Ficha]:[Nombre]],2,FALSE)),"-") -> LUCIO ALFONSO POSADAS RAMIREZ | S23: =IF(N23="Cancelado","◄ ◄ ◄ Favor de indicar la causa","-") -> - | U23: SPRMSO | V23: =COUNTIFS($L$14:$L$300,V$15,$C$14:$C$300,$U23,$N$14:$N$300,"Realizado") -> 0 | W23: =COUNTIFS($L$14:$L$300,W$15,$C$14:$C$300,$U23,$N$14:$N$300,"Realizado") -> 0 | X23: =COUNTIFS($L$14:$L$300,X$15,$C$14:$C$300,$U23,$N$14:$N$300,"Realizado") -> 0 | Y23: =COUNTIFS($L$14:$L$300,Y$15,$C$14:$C$300,$U23,$N$14:$N$300,"Realizado") -> 0 | Z23: =COUNTIFS($L$14:$L$300,Z$15,$C$14:$C$300,$U23,$N$14:$N$300,"Realizado") -> 0 | AA23: =COUNTIFS($L$14:$L$300,AA$15,$C$14:$C$300,$U23,$N$14:$N$300,"Realizado") -> 0 | AB23: =COUNTIFS($L$14:$L$300,AB$15,$C$14:$C$300,$U23,$N$14:$N$300,"Realizado") -> 0 | AC23: =COUNTIFS($L$14:$L$300,AC$15,$C$14:$C$300,$U23,$N$14:$N$300,"Realizado") -> 0 | ... AG23: =COUNTIFS($L$14:$L$300,AG$15,$C$14:$C$300,$U23,$N$14:$N$300,"Realizado") -> 0 | AH23: =SUM(V23:AG23) -> 0
A24: 52274 | C24: SPRN | D24: ACTIVO DE PRODUCCIÓN REYNOSA | E24: PROCEDIMIENTOS CRÍTICOS (PC) | F24: 196157 | G24: POSADAS RAMÍREZ LUCIO ALFONSO | H24: 14 | I24: 45036 | J24: 45037 | K24: REYNOSA, TAMAULIPAS | L24: =MONTH(J24) -> 4 | M24: =IF(AND(J24>=$B$2,J24<=$C$2),1,0) -> 1 | N24: Realizado | O24: 13 | P24: 196157 | Q24: =IFERROR((VLOOKUP(P24,Padrón[[Ficha]:[Nombre]],2,FALSE)),"-") -> LUCIO ALFONSO POSADAS RAMIREZ | S24: =IF(N24="Cancelado","◄ ◄ ◄ Favor de indicar la causa","-") -> - | U24: SPRN | V24: =COUNTIFS($L$14:$L$300,V$15,$C$14:$C$300,$U24,$N$14:$N$300,"Realizado") -> 0 | W24: =COUNTIFS($L$14:$L$300,W$15,$C$14:$C$300,$U24,$N$14:$N$300,"Realizado") -> 1 | X24: =COUNTIFS($L$14:$L$300,X$15,$C$14:$C$300,$U24,$N$14:$N$300,"Realizado") -> 4 | Y24: =COUNTIFS($L$14:$L$300,Y$15,$C$14:$C$300,$U24,$N$14:$N$300,"Realizado") -> 8 | Z24: =COUNTIFS($L$14:$L$300,Z$15,$C$14:$C$300,$U24,$N$14:$N$300,"Realizado") -> 13 | AA24: =COUNTIFS($L$14:$L$300,AA$15,$C$14:$C$300,$U24,$N$14:$N$300,"Realizado") -> 9 | AB24: =COUNTIFS($L$14:$L$300,AB$15,$C$14:$C$300,$U24,$N$14:$N$300,"Realizado") -> 0 | AC24: =COUNTIFS($L$14:$L$300,AC$15,$C$14:$C$300,$U24,$N$14:$N$300,"Realizado") -> 1 | ... AG24: =COUNTIFS($L$14:$L$300,AG$15,$C$14:$C$300,$U24,$N$14:$N$300,"Realizado") -> 0 | AH24: =SUM(V24:AG24) -> 50
A25: 47009 | C25: SPRN | D25: GERENCIA DE MANTENIMIENTO, CONFIABILIDAD Y CONSTRUCCIÓN | E25: BÁSICO DE SEGURIDAD (BS) | F25: 196157 | G25: POSADAS RAMÍREZ LUCIO ALFONSO | H25: 14 | I25: 45040 | J25: 45041 | K25: REYNOSA, TAMAULIPAS | L25: =MONTH(J25) -> 4 | M25: =IF(AND(J25>=$B$2,J25<=$C$2),1,0) -> 1 | N25: Realizado | O25: 14 | P25: 196157 | Q25: =IFERROR((VLOOKUP(P25,Padrón[[Ficha]:[Nombre]],2,FALSE)),"-") -> LUCIO ALFONSO POSADAS RAMIREZ | S25: =IF(N25="Cancelado","◄ ◄ ◄ Favor de indicar la causa","-") -> - | U25: SPRS | V25: =COUNTIFS($L$14:$L$300,V$15,$C$14:$C$300,$U25,$N$14:$N$300,"Realizado") -> 0 | W25: =COUNTIFS($L$14:$L$300,W$15,$C$14:$C$300,$U25,$N$14:$N$300,"Realizado") -> 0 | X25: =COUNTIFS($L$14:$L$300,X$15,$C$14:$C$300,$U25,$N$14:$N$300,"Realizado") -> 0 | Y25: =COUNTIFS($L$14:$L$300,Y$15,$C$14:$C$300,$U25,$N$14:$N$300,"Realizado") -> 0 | Z25: =COUNTIFS($L$14:$L$300,Z$15,$C$14:$C$300,$U25,$N$14:$N$300,"Realizado") -> 0 | AA25: =COUNTIFS($L$14:$L$300,AA$15,$C$14:$C$300,$U25,$N$14:$N$300,"Realizado") -> 0 | AB25: =COUNTIFS($L$14:$L$300,AB$15,$C$14:$C$300,$U25,$N$14:$N$300,"Realizado") -> 0 | AC25: =COUNTIFS($L$14:$L$300,AC$15,$C$14:$C$300,$U25,$N$14:$N$300,"Realizado") -> 0 | ... AG25: =COUNTIFS($L$14:$L$300,AG$15,$C$14:$C$300,$U25,$N$14:$N$300,"Realizado") -> 0 | AH25: =SUM(V25:AG25) -> 0
A26: 47004 | C26: SPRN | D26: GERENCIA DE MANTENIMIENTO, CONFIABILIDAD Y CONSTRUCCIÓN | E26: BÁSICO DE SEGURIDAD (BS) | F26: 196157 | G26: POSADAS RAMÍREZ LUCIO ALFONSO | H26: 15 | I26: 45042 | J26: 45043 | K26: REYNOSA, TAMAULIPAS | L26: =MONTH(J26) -> 4 | M26: =IF(AND(J26>=$B$2,J26<=$C$2),1,0) -> 1 | N26: Realizado | O26: 14 | P26: 196157 | Q26: =IFERROR((VLOOKUP(P26,Padrón[[Ficha]:[Nombre]],2,FALSE)),"-") -> LUCIO ALFONSO POSADAS RAMIREZ | S26: =IF(N26="Cancelado","◄ ◄ ◄ Favor de indicar la causa","-") -> - | U26: SSSTPA | V26: =COUNTIFS($L$14:$L$300,V$15,$C$14:$C$300,$U26,$N$14:$N$300,"Realizado") -> 0 | W26: =COUNTIFS($L$14:$L$300,W$15,$C$14:$C$300,$U26,$N$14:$N$300,"Realizado") -> 0 | X26: =COUNTIFS($L$14:$L$300,X$15,$C$14:$C$300,$U26,$N$14:$N$300,"Realizado") -> 0 | Y26: =COUNTIFS($L$14:$L$300,Y$15,$C$14:$C$300,$U26,$N$14:$N$300,"Realizado") -> 0 | Z26: =COUNTIFS($L$14:$L$300,Z$15,$C$14:$C$300,$U26,$N$14:$N$300,"Realizado") -> 4 | AA26: =COUNTIFS($L$14:$L$300,AA$15,$C$14:$C$300,$U26,$N$14:$N$300,"Realizado") -> 5 | AB26: =COUNTIFS($L$14:$L$300,AB$15,$C$14:$C$300,$U26,$N$14:$N$300,"Realizado") -> 0 | AC26: =COUNTIFS($L$14:$L$300,AC$15,$C$14:$C$300,$U26,$N$14:$N$300,"Realizado") -> 0 | ... AG26: =COUNTIFS($L$14:$L$300,AG$15,$C$14:$C$300,$U26,$N$14:$N$300,"Realizado") -> 0 | AH26: =SUM(V26:AG26) -> 9
A27: 58119 | C27: SPRN | D27: ACTIVO DE PRODUCCIÓN REYNOSA | E27: ADMINISTRACIÓN DE RIESGOS EN LOS PROCESOS DE PEMEX EXPLORACIÓN Y PRODUCCIÓN (ARP PEP) | F27: 375324 | G27: MADRIGAL ELISEO DAVID MICHAEL | H27: 7 | I27: 45054 | J27: 45054 | K27: REYNOSA, TAMAULIPAS | L27: =MONTH(J27) -> 5 | M27: =IF(AND(J27>=$B$2,J27<=$C$2),1,0) -> 1 | N27: Realizado | O27: 7 | P27: 375324 | Q27: =IFERROR((VLOOKUP(P27,Padrón[[Ficha]:[Nombre]],2,FALSE)),"-") -> DAVID MICHAEL MADRIGAL ELISEO | S27: =IF(N27="Cancelado","◄ ◄ ◄ Favor de indicar la causa","-") -> - | U27: Total | V27: =SUM(V16:V26) -> 0 | W27: =SUM(W16:W26) -> 1 | X27: =SUM(X16:X26) -> 4 | Y27: =SUM(Y16:Y26) -> 8 | Z27: =SUM(Z16:Z26) -> 17 | AA27: =SUM(AA16:AA26) -> 19 | AB27: =SUM(AB16:AB26) -> 0 | AC27: =SUM(AC16:AC26) -> 1 | ... AH27: =SUM(AH16:AH26) -> 66
A28: 47023 | C28: SPRN | D28: GERENCIA DE MANTENIMIENTO, CONFIABILIDAD Y CONSTRUCCIÓN | E28: REVALIDACIÓN BÁSICO DE SEGURIDAD (BS) | F28: 196157 | G28: POSADAS RAMÍREZ LUCIO ALFONSO | H28: 18 | I28: 45054 | J28: 45054 | K28: REYNOSA, TAMAULIPAS | L28: =MONTH(J28) -> 5 | M28: =IF(AND(J28>=$B$2,J28<=$C$2),1,0) -> 1 | N28: Realizado | O28: 20 | P28: 348492 | Q28: CLAUDIA CONSUELO CUÉLLAR BURELA | S28: =IF(N28="Cancelado","◄ ◄ ◄ Favor de indicar la causa","-") -> -
A29: 47971 | C29: SPRN | D29: ACTIVO DE PRODUCCIÓN REYNOSA | E29: DISCIPLINA OPERATIVA (DO) | F29: 196157 | G29: POSADAS RAMÍREZ LUCIO ALFONSO | H29: 19 | I29: 45057 | J29: 45058 | K29: REYNOSA, TAMAULIPAS | L29: =MONTH(J29) -> 5 | M29: =IF(AND(J29>=$B$2,J29<=$C$2),1,0) -> 1 | N29: Realizado | O29: 16 | P29: 196157 | Q29: =IFERROR((VLOOKUP(P29,Padrón[[Ficha]:[Nombre]],2,FALSE)),"-") -> LUCIO ALFONSO POSADAS RAMIREZ | S29: =IF(N29="Cancelado","◄ ◄ ◄ Favor de indicar la causa","-") -> - | U29: Cancelados | V29: 1 | W29: 2 | X29: 3 | Y29: 4 | Z29: 5 | AA29: 6 | AB29: 7 | AC29: 8 | AD29: 9 | AE29: 10 | AF29: 11 | AG29: 12 | AH29: Total
